[2025-02-20T06:06:25.330+0000] {local_task_job_runner.py:120} INFO - ::group::Pre task execution logs
[2025-02-20T06:06:25.387+0000] {taskinstance.py:2073} INFO - Dependencies all met for dep_context=non-requeueable deps ti=<TaskInstance: real_estate_scraper.scrape_real_estate_data manual__2025-02-20T06:00:19.135863+00:00 [queued]>
[2025-02-20T06:06:25.408+0000] {taskinstance.py:2073} INFO - Dependencies all met for dep_context=requeueable deps ti=<TaskInstance: real_estate_scraper.scrape_real_estate_data manual__2025-02-20T06:00:19.135863+00:00 [queued]>
[2025-02-20T06:06:25.412+0000] {taskinstance.py:2303} INFO - Starting attempt 2 of 2
[2025-02-20T06:06:25.723+0000] {taskinstance.py:2327} INFO - Executing <Task(PythonOperator): scrape_real_estate_data> on 2025-02-20 06:00:19.135863+00:00
[2025-02-20T06:06:25.733+0000] {standard_task_runner.py:63} INFO - Started process 190 to run task
[2025-02-20T06:06:25.742+0000] {standard_task_runner.py:90} INFO - Running: ['***', 'tasks', 'run', 'real_estate_scraper', 'scrape_real_estate_data', 'manual__2025-02-20T06:00:19.135863+00:00', '--job-id', '18', '--raw', '--subdir', 'DAGS_FOLDER/scrape_push.py', '--cfg-path', '/tmp/tmp8pkqvrx7']
[2025-02-20T06:06:25.748+0000] {standard_task_runner.py:91} INFO - Job 18: Subtask scrape_real_estate_data
[2025-02-20T06:06:25.902+0000] {task_command.py:426} INFO - Running <TaskInstance: real_estate_scraper.scrape_real_estate_data manual__2025-02-20T06:00:19.135863+00:00 [running]> on host 9ed406e2e34d
[2025-02-20T06:06:26.083+0000] {taskinstance.py:2644} INFO - Exporting env vars: AIRFLOW_CTX_DAG_OWNER='***' AIRFLOW_CTX_DAG_ID='real_estate_scraper' AIRFLOW_CTX_TASK_ID='scrape_real_estate_data' AIRFLOW_CTX_EXECUTION_DATE='2025-02-20T06:00:19.135863+00:00' AIRFLOW_CTX_TRY_NUMBER='2' AIRFLOW_CTX_DAG_RUN_ID='manual__2025-02-20T06:00:19.135863+00:00'
[2025-02-20T06:06:26.085+0000] {taskinstance.py:430} INFO - ::endgroup::
[2025-02-20T06:06:26.137+0000] {logger.py:11} INFO - ====== WebDriver manager ======
[2025-02-20T06:06:26.520+0000] {logger.py:11} INFO - Get LATEST chromedriver version for google-chrome
[2025-02-20T06:06:26.926+0000] {logger.py:11} INFO - Get LATEST chromedriver version for google-chrome
[2025-02-20T06:06:27.166+0000] {logger.py:11} INFO - There is no [linux64] chromedriver "133.0.6943.126" for browser google-chrome "133.0.6943" in cache
[2025-02-20T06:06:27.167+0000] {logger.py:11} INFO - Get LATEST chromedriver version for google-chrome
[2025-02-20T06:06:27.703+0000] {logger.py:11} INFO - WebDriver version 133.0.6943.126 selected
[2025-02-20T06:06:27.714+0000] {logger.py:11} INFO - Modern chrome version https://storage.googleapis.com/chrome-for-testing-public/133.0.6943.126/linux64/chromedriver-linux64.zip
[2025-02-20T06:06:27.715+0000] {logger.py:11} INFO - About to download new driver from https://storage.googleapis.com/chrome-for-testing-public/133.0.6943.126/linux64/chromedriver-linux64.zip
[2025-02-20T06:06:28.019+0000] {logger.py:11} INFO - Driver downloading response is 200
[2025-02-20T06:06:31.254+0000] {logger.py:11} INFO - Get LATEST chromedriver version for google-chrome
[2025-02-20T06:06:31.685+0000] {logger.py:11} INFO - Driver has been saved in cache [/home/***/.wdm/drivers/chromedriver/linux64/133.0.6943.126]
[2025-02-20T06:06:32.723+0000] {taskinstance.py:441} INFO - ::group::Post task execution logs
[2025-02-20T06:06:32.725+0000] {taskinstance.py:2890} ERROR - Task failed with exception
Traceback (most recent call last):
  File "/home/airflow/.local/lib/python3.9/site-packages/airflow/models/taskinstance.py", line 465, in _execute_task
    result = _execute_callable(context=context, **execute_callable_kwargs)
  File "/home/airflow/.local/lib/python3.9/site-packages/airflow/models/taskinstance.py", line 432, in _execute_callable
    return execute_callable(context=context, **execute_callable_kwargs)
  File "/home/airflow/.local/lib/python3.9/site-packages/airflow/models/baseoperator.py", line 400, in wrapper
    return func(self, *args, **kwargs)
  File "/home/airflow/.local/lib/python3.9/site-packages/airflow/operators/python.py", line 235, in execute
    return_value = self.execute_callable()
  File "/home/airflow/.local/lib/python3.9/site-packages/airflow/operators/python.py", line 252, in execute_callable
    return self.python_callable(*self.op_args, **self.op_kwargs)
  File "/opt/airflow/dags/scrape_push.py", line 14, in scrape_real_estate
    driver = webdriver.Chrome(service=Service(ChromeDriverManager().install()))
  File "/home/airflow/.local/lib/python3.9/site-packages/selenium/webdriver/chrome/webdriver.py", line 45, in __init__
    super().__init__(
  File "/home/airflow/.local/lib/python3.9/site-packages/selenium/webdriver/chromium/webdriver.py", line 56, in __init__
    super().__init__(
  File "/home/airflow/.local/lib/python3.9/site-packages/selenium/webdriver/remote/webdriver.py", line 205, in __init__
    self.start_session(capabilities)
  File "/home/airflow/.local/lib/python3.9/site-packages/selenium/webdriver/remote/webdriver.py", line 289, in start_session
    response = self.execute(Command.NEW_SESSION, caps)["value"]
  File "/home/airflow/.local/lib/python3.9/site-packages/selenium/webdriver/remote/webdriver.py", line 344, in execute
    self.error_handler.check_response(response)
  File "/home/airflow/.local/lib/python3.9/site-packages/selenium/webdriver/remote/errorhandler.py", line 229, in check_response
    raise exception_class(message, screen, stacktrace)
selenium.common.exceptions.SessionNotCreatedException: Message: session not created: probably user data directory is already in use, please specify a unique value for --user-data-dir argument, or don't use --user-data-dir
Stacktrace:
#0 0x559271179bea <unknown>
#1 0x559270c177d0 <unknown>
#2 0x559270c50c05 <unknown>
#3 0x559270c4c96f <unknown>
#4 0x559270c9d3a9 <unknown>
#5 0x559270c9c8d6 <unknown>
#6 0x559270c8e863 <unknown>
#7 0x559270c5aac8 <unknown>
#8 0x559270c5bc31 <unknown>
#9 0x55927114318b <unknown>
#10 0x559271147112 <unknown>
#11 0x55927113004c <unknown>
#12 0x559271147d04 <unknown>
#13 0x5592711144bf <unknown>
#14 0x559271168528 <unknown>
#15 0x5592711686f9 <unknown>
#16 0x559271178a66 <unknown>
#17 0x7f33775111c4 <unknown>

[2025-02-20T06:06:32.753+0000] {taskinstance.py:1205} INFO - Marking task as FAILED. dag_id=real_estate_scraper, task_id=scrape_real_estate_data, execution_date=20250220T060019, start_date=20250220T060625, end_date=20250220T060632
[2025-02-20T06:06:32.782+0000] {standard_task_runner.py:110} ERROR - Failed to execute job 18 for task scrape_real_estate_data (Message: session not created: probably user data directory is already in use, please specify a unique value for --user-data-dir argument, or don't use --user-data-dir
Stacktrace:
#0 0x559271179bea <unknown>
#1 0x559270c177d0 <unknown>
#2 0x559270c50c05 <unknown>
#3 0x559270c4c96f <unknown>
#4 0x559270c9d3a9 <unknown>
#5 0x559270c9c8d6 <unknown>
#6 0x559270c8e863 <unknown>
#7 0x559270c5aac8 <unknown>
#8 0x559270c5bc31 <unknown>
#9 0x55927114318b <unknown>
#10 0x559271147112 <unknown>
#11 0x55927113004c <unknown>
#12 0x559271147d04 <unknown>
#13 0x5592711144bf <unknown>
#14 0x559271168528 <unknown>
#15 0x5592711686f9 <unknown>
#16 0x559271178a66 <unknown>
#17 0x7f33775111c4 <unknown>
; 190)
[2025-02-20T06:06:32.805+0000] {local_task_job_runner.py:240} INFO - Task exited with return code 1
[2025-02-20T06:06:32.846+0000] {taskinstance.py:3482} INFO - 0 downstream tasks scheduled from follow-on schedule check
[2025-02-20T06:06:32.855+0000] {local_task_job_runner.py:222} INFO - ::endgroup::
