[2025-01-19T14:30:20.896+0000] {processor.py:161} INFO - Started process (PID=88412) to work on /opt/airflow/dags/bigC_1.py
[2025-01-19T14:30:20.897+0000] {processor.py:830} INFO - Processing file /opt/airflow/dags/bigC_1.py for tasks to queue
[2025-01-19T14:30:20.897+0000] {logging_mixin.py:188} INFO - [2025-01-19T14:30:20.897+0000] {dagbag.py:540} INFO - Filling up the DagBag from /opt/airflow/dags/bigC_1.py
[2025-01-19T14:30:20.899+0000] {logging_mixin.py:188} INFO - [2025-01-19T14:30:20.899+0000] {dagbag.py:350} ERROR - Failed to import: /opt/airflow/dags/bigC_1.py
Traceback (most recent call last):
  File "/home/airflow/.local/lib/python3.9/site-packages/airflow/models/dagbag.py", line 346, in parse
    loader.exec_module(new_module)
  File "<frozen importlib._bootstrap_external>", line 846, in exec_module
  File "<frozen importlib._bootstrap_external>", line 983, in get_code
  File "<frozen importlib._bootstrap_external>", line 913, in source_to_code
  File "<frozen importlib._bootstrap>", line 228, in _call_with_frames_removed
  File "/opt/airflow/dags/bigC_1.py", line 1
    rom airflow import DAG
        ^
SyntaxError: invalid syntax
[2025-01-19T14:30:20.899+0000] {processor.py:842} WARNING - No viable dags retrieved from /opt/airflow/dags/bigC_1.py
[2025-01-19T14:30:20.910+0000] {processor.py:183} INFO - Processing /opt/airflow/dags/bigC_1.py took 0.016 seconds
[2025-01-19T14:30:51.354+0000] {processor.py:161} INFO - Started process (PID=88541) to work on /opt/airflow/dags/bigC_1.py
[2025-01-19T14:30:51.355+0000] {processor.py:830} INFO - Processing file /opt/airflow/dags/bigC_1.py for tasks to queue
[2025-01-19T14:30:51.356+0000] {logging_mixin.py:188} INFO - [2025-01-19T14:30:51.356+0000] {dagbag.py:540} INFO - Filling up the DagBag from /opt/airflow/dags/bigC_1.py
[2025-01-19T14:30:51.357+0000] {logging_mixin.py:188} INFO - [2025-01-19T14:30:51.357+0000] {dagbag.py:350} ERROR - Failed to import: /opt/airflow/dags/bigC_1.py
Traceback (most recent call last):
  File "/home/airflow/.local/lib/python3.9/site-packages/airflow/models/dagbag.py", line 346, in parse
    loader.exec_module(new_module)
  File "<frozen importlib._bootstrap_external>", line 846, in exec_module
  File "<frozen importlib._bootstrap_external>", line 983, in get_code
  File "<frozen importlib._bootstrap_external>", line 913, in source_to_code
  File "<frozen importlib._bootstrap>", line 228, in _call_with_frames_removed
  File "/opt/airflow/dags/bigC_1.py", line 1
    rom airflow import DAG
        ^
SyntaxError: invalid syntax
[2025-01-19T14:30:51.357+0000] {processor.py:842} WARNING - No viable dags retrieved from /opt/airflow/dags/bigC_1.py
[2025-01-19T14:30:51.367+0000] {processor.py:183} INFO - Processing /opt/airflow/dags/bigC_1.py took 0.017 seconds
[2025-01-19T14:31:21.822+0000] {processor.py:161} INFO - Started process (PID=88663) to work on /opt/airflow/dags/bigC_1.py
[2025-01-19T14:31:21.823+0000] {processor.py:830} INFO - Processing file /opt/airflow/dags/bigC_1.py for tasks to queue
[2025-01-19T14:31:21.824+0000] {logging_mixin.py:188} INFO - [2025-01-19T14:31:21.824+0000] {dagbag.py:540} INFO - Filling up the DagBag from /opt/airflow/dags/bigC_1.py
[2025-01-19T14:31:21.826+0000] {logging_mixin.py:188} INFO - [2025-01-19T14:31:21.825+0000] {dagbag.py:350} ERROR - Failed to import: /opt/airflow/dags/bigC_1.py
Traceback (most recent call last):
  File "/home/airflow/.local/lib/python3.9/site-packages/airflow/models/dagbag.py", line 346, in parse
    loader.exec_module(new_module)
  File "<frozen importlib._bootstrap_external>", line 846, in exec_module
  File "<frozen importlib._bootstrap_external>", line 983, in get_code
  File "<frozen importlib._bootstrap_external>", line 913, in source_to_code
  File "<frozen importlib._bootstrap>", line 228, in _call_with_frames_removed
  File "/opt/airflow/dags/bigC_1.py", line 1
    rom airflow import DAG
        ^
SyntaxError: invalid syntax
[2025-01-19T14:31:21.826+0000] {processor.py:842} WARNING - No viable dags retrieved from /opt/airflow/dags/bigC_1.py
[2025-01-19T14:31:21.835+0000] {processor.py:183} INFO - Processing /opt/airflow/dags/bigC_1.py took 0.016 seconds
[2025-01-19T14:31:52.457+0000] {processor.py:161} INFO - Started process (PID=88792) to work on /opt/airflow/dags/bigC_1.py
[2025-01-19T14:31:52.458+0000] {processor.py:830} INFO - Processing file /opt/airflow/dags/bigC_1.py for tasks to queue
[2025-01-19T14:31:52.459+0000] {logging_mixin.py:188} INFO - [2025-01-19T14:31:52.459+0000] {dagbag.py:540} INFO - Filling up the DagBag from /opt/airflow/dags/bigC_1.py
[2025-01-19T14:31:52.460+0000] {logging_mixin.py:188} INFO - [2025-01-19T14:31:52.460+0000] {dagbag.py:350} ERROR - Failed to import: /opt/airflow/dags/bigC_1.py
Traceback (most recent call last):
  File "/home/airflow/.local/lib/python3.9/site-packages/airflow/models/dagbag.py", line 346, in parse
    loader.exec_module(new_module)
  File "<frozen importlib._bootstrap_external>", line 846, in exec_module
  File "<frozen importlib._bootstrap_external>", line 983, in get_code
  File "<frozen importlib._bootstrap_external>", line 913, in source_to_code
  File "<frozen importlib._bootstrap>", line 228, in _call_with_frames_removed
  File "/opt/airflow/dags/bigC_1.py", line 1
    rom airflow import DAG
        ^
SyntaxError: invalid syntax
[2025-01-19T14:31:52.461+0000] {processor.py:842} WARNING - No viable dags retrieved from /opt/airflow/dags/bigC_1.py
[2025-01-19T14:31:52.471+0000] {processor.py:183} INFO - Processing /opt/airflow/dags/bigC_1.py took 0.017 seconds
[2025-01-19T14:32:22.919+0000] {processor.py:161} INFO - Started process (PID=88921) to work on /opt/airflow/dags/bigC_1.py
[2025-01-19T14:32:22.920+0000] {processor.py:830} INFO - Processing file /opt/airflow/dags/bigC_1.py for tasks to queue
[2025-01-19T14:32:22.921+0000] {logging_mixin.py:188} INFO - [2025-01-19T14:32:22.921+0000] {dagbag.py:540} INFO - Filling up the DagBag from /opt/airflow/dags/bigC_1.py
[2025-01-19T14:32:22.923+0000] {logging_mixin.py:188} INFO - [2025-01-19T14:32:22.922+0000] {dagbag.py:350} ERROR - Failed to import: /opt/airflow/dags/bigC_1.py
Traceback (most recent call last):
  File "/home/airflow/.local/lib/python3.9/site-packages/airflow/models/dagbag.py", line 346, in parse
    loader.exec_module(new_module)
  File "<frozen importlib._bootstrap_external>", line 846, in exec_module
  File "<frozen importlib._bootstrap_external>", line 983, in get_code
  File "<frozen importlib._bootstrap_external>", line 913, in source_to_code
  File "<frozen importlib._bootstrap>", line 228, in _call_with_frames_removed
  File "/opt/airflow/dags/bigC_1.py", line 1
    rom airflow import DAG
        ^
SyntaxError: invalid syntax
[2025-01-19T14:32:22.923+0000] {processor.py:842} WARNING - No viable dags retrieved from /opt/airflow/dags/bigC_1.py
[2025-01-19T14:32:22.933+0000] {processor.py:183} INFO - Processing /opt/airflow/dags/bigC_1.py took 0.017 seconds
[2025-01-19T14:32:53.558+0000] {processor.py:161} INFO - Started process (PID=89043) to work on /opt/airflow/dags/bigC_1.py
[2025-01-19T14:32:53.559+0000] {processor.py:830} INFO - Processing file /opt/airflow/dags/bigC_1.py for tasks to queue
[2025-01-19T14:32:53.560+0000] {logging_mixin.py:188} INFO - [2025-01-19T14:32:53.560+0000] {dagbag.py:540} INFO - Filling up the DagBag from /opt/airflow/dags/bigC_1.py
[2025-01-19T14:32:53.561+0000] {logging_mixin.py:188} INFO - [2025-01-19T14:32:53.561+0000] {dagbag.py:350} ERROR - Failed to import: /opt/airflow/dags/bigC_1.py
Traceback (most recent call last):
  File "/home/airflow/.local/lib/python3.9/site-packages/airflow/models/dagbag.py", line 346, in parse
    loader.exec_module(new_module)
  File "<frozen importlib._bootstrap_external>", line 846, in exec_module
  File "<frozen importlib._bootstrap_external>", line 983, in get_code
  File "<frozen importlib._bootstrap_external>", line 913, in source_to_code
  File "<frozen importlib._bootstrap>", line 228, in _call_with_frames_removed
  File "/opt/airflow/dags/bigC_1.py", line 1
    rom airflow import DAG
        ^
SyntaxError: invalid syntax
[2025-01-19T14:32:53.561+0000] {processor.py:842} WARNING - No viable dags retrieved from /opt/airflow/dags/bigC_1.py
[2025-01-19T14:32:53.571+0000] {processor.py:183} INFO - Processing /opt/airflow/dags/bigC_1.py took 0.017 seconds
[2025-01-19T14:33:24.094+0000] {processor.py:161} INFO - Started process (PID=89172) to work on /opt/airflow/dags/bigC_1.py
[2025-01-19T14:33:24.095+0000] {processor.py:830} INFO - Processing file /opt/airflow/dags/bigC_1.py for tasks to queue
[2025-01-19T14:33:24.096+0000] {logging_mixin.py:188} INFO - [2025-01-19T14:33:24.096+0000] {dagbag.py:540} INFO - Filling up the DagBag from /opt/airflow/dags/bigC_1.py
[2025-01-19T14:33:24.098+0000] {logging_mixin.py:188} INFO - [2025-01-19T14:33:24.097+0000] {dagbag.py:350} ERROR - Failed to import: /opt/airflow/dags/bigC_1.py
Traceback (most recent call last):
  File "/home/airflow/.local/lib/python3.9/site-packages/airflow/models/dagbag.py", line 346, in parse
    loader.exec_module(new_module)
  File "<frozen importlib._bootstrap_external>", line 846, in exec_module
  File "<frozen importlib._bootstrap_external>", line 983, in get_code
  File "<frozen importlib._bootstrap_external>", line 913, in source_to_code
  File "<frozen importlib._bootstrap>", line 228, in _call_with_frames_removed
  File "/opt/airflow/dags/bigC_1.py", line 1
    rom airflow import DAG
        ^
SyntaxError: invalid syntax
[2025-01-19T14:33:24.098+0000] {processor.py:842} WARNING - No viable dags retrieved from /opt/airflow/dags/bigC_1.py
[2025-01-19T14:33:24.109+0000] {processor.py:183} INFO - Processing /opt/airflow/dags/bigC_1.py took 0.018 seconds
[2025-01-19T14:33:54.724+0000] {processor.py:161} INFO - Started process (PID=89301) to work on /opt/airflow/dags/bigC_1.py
[2025-01-19T14:33:54.725+0000] {processor.py:830} INFO - Processing file /opt/airflow/dags/bigC_1.py for tasks to queue
[2025-01-19T14:33:54.726+0000] {logging_mixin.py:188} INFO - [2025-01-19T14:33:54.726+0000] {dagbag.py:540} INFO - Filling up the DagBag from /opt/airflow/dags/bigC_1.py
[2025-01-19T14:33:54.728+0000] {logging_mixin.py:188} INFO - [2025-01-19T14:33:54.727+0000] {dagbag.py:350} ERROR - Failed to import: /opt/airflow/dags/bigC_1.py
Traceback (most recent call last):
  File "/home/airflow/.local/lib/python3.9/site-packages/airflow/models/dagbag.py", line 346, in parse
    loader.exec_module(new_module)
  File "<frozen importlib._bootstrap_external>", line 846, in exec_module
  File "<frozen importlib._bootstrap_external>", line 983, in get_code
  File "<frozen importlib._bootstrap_external>", line 913, in source_to_code
  File "<frozen importlib._bootstrap>", line 228, in _call_with_frames_removed
  File "/opt/airflow/dags/bigC_1.py", line 1
    rom airflow import DAG
        ^
SyntaxError: invalid syntax
[2025-01-19T14:33:54.728+0000] {processor.py:842} WARNING - No viable dags retrieved from /opt/airflow/dags/bigC_1.py
[2025-01-19T14:33:54.738+0000] {processor.py:183} INFO - Processing /opt/airflow/dags/bigC_1.py took 0.017 seconds
[2025-01-19T14:34:25.541+0000] {processor.py:161} INFO - Started process (PID=89423) to work on /opt/airflow/dags/bigC_1.py
[2025-01-19T14:34:25.542+0000] {processor.py:830} INFO - Processing file /opt/airflow/dags/bigC_1.py for tasks to queue
[2025-01-19T14:34:25.543+0000] {logging_mixin.py:188} INFO - [2025-01-19T14:34:25.543+0000] {dagbag.py:540} INFO - Filling up the DagBag from /opt/airflow/dags/bigC_1.py
[2025-01-19T14:34:25.545+0000] {logging_mixin.py:188} INFO - [2025-01-19T14:34:25.544+0000] {dagbag.py:350} ERROR - Failed to import: /opt/airflow/dags/bigC_1.py
Traceback (most recent call last):
  File "/home/airflow/.local/lib/python3.9/site-packages/airflow/models/dagbag.py", line 346, in parse
    loader.exec_module(new_module)
  File "<frozen importlib._bootstrap_external>", line 846, in exec_module
  File "<frozen importlib._bootstrap_external>", line 983, in get_code
  File "<frozen importlib._bootstrap_external>", line 913, in source_to_code
  File "<frozen importlib._bootstrap>", line 228, in _call_with_frames_removed
  File "/opt/airflow/dags/bigC_1.py", line 1
    rom airflow import DAG
        ^
SyntaxError: invalid syntax
[2025-01-19T14:34:25.545+0000] {processor.py:842} WARNING - No viable dags retrieved from /opt/airflow/dags/bigC_1.py
[2025-01-19T14:34:25.555+0000] {processor.py:183} INFO - Processing /opt/airflow/dags/bigC_1.py took 0.018 seconds
[2025-01-19T14:34:56.453+0000] {processor.py:161} INFO - Started process (PID=89552) to work on /opt/airflow/dags/bigC_1.py
[2025-01-19T14:34:56.454+0000] {processor.py:830} INFO - Processing file /opt/airflow/dags/bigC_1.py for tasks to queue
[2025-01-19T14:34:56.454+0000] {logging_mixin.py:188} INFO - [2025-01-19T14:34:56.454+0000] {dagbag.py:540} INFO - Filling up the DagBag from /opt/airflow/dags/bigC_1.py
[2025-01-19T14:34:56.456+0000] {logging_mixin.py:188} INFO - [2025-01-19T14:34:56.456+0000] {dagbag.py:350} ERROR - Failed to import: /opt/airflow/dags/bigC_1.py
Traceback (most recent call last):
  File "/home/airflow/.local/lib/python3.9/site-packages/airflow/models/dagbag.py", line 346, in parse
    loader.exec_module(new_module)
  File "<frozen importlib._bootstrap_external>", line 846, in exec_module
  File "<frozen importlib._bootstrap_external>", line 983, in get_code
  File "<frozen importlib._bootstrap_external>", line 913, in source_to_code
  File "<frozen importlib._bootstrap>", line 228, in _call_with_frames_removed
  File "/opt/airflow/dags/bigC_1.py", line 1
    rom airflow import DAG
        ^
SyntaxError: invalid syntax
[2025-01-19T14:34:56.456+0000] {processor.py:842} WARNING - No viable dags retrieved from /opt/airflow/dags/bigC_1.py
[2025-01-19T14:34:56.466+0000] {processor.py:183} INFO - Processing /opt/airflow/dags/bigC_1.py took 0.016 seconds
[2025-01-19T14:35:26.533+0000] {processor.py:161} INFO - Started process (PID=89681) to work on /opt/airflow/dags/bigC_1.py
[2025-01-19T14:35:26.534+0000] {processor.py:830} INFO - Processing file /opt/airflow/dags/bigC_1.py for tasks to queue
[2025-01-19T14:35:26.535+0000] {logging_mixin.py:188} INFO - [2025-01-19T14:35:26.535+0000] {dagbag.py:540} INFO - Filling up the DagBag from /opt/airflow/dags/bigC_1.py
[2025-01-19T14:35:26.536+0000] {logging_mixin.py:188} INFO - [2025-01-19T14:35:26.536+0000] {dagbag.py:350} ERROR - Failed to import: /opt/airflow/dags/bigC_1.py
Traceback (most recent call last):
  File "/home/airflow/.local/lib/python3.9/site-packages/airflow/models/dagbag.py", line 346, in parse
    loader.exec_module(new_module)
  File "<frozen importlib._bootstrap_external>", line 846, in exec_module
  File "<frozen importlib._bootstrap_external>", line 983, in get_code
  File "<frozen importlib._bootstrap_external>", line 913, in source_to_code
  File "<frozen importlib._bootstrap>", line 228, in _call_with_frames_removed
  File "/opt/airflow/dags/bigC_1.py", line 1
    rom airflow import DAG
        ^
SyntaxError: invalid syntax
[2025-01-19T14:35:26.536+0000] {processor.py:842} WARNING - No viable dags retrieved from /opt/airflow/dags/bigC_1.py
[2025-01-19T14:35:26.548+0000] {processor.py:183} INFO - Processing /opt/airflow/dags/bigC_1.py took 0.018 seconds
[2025-01-19T14:35:56.731+0000] {processor.py:161} INFO - Started process (PID=89798) to work on /opt/airflow/dags/bigC_1.py
[2025-01-19T14:35:56.732+0000] {processor.py:830} INFO - Processing file /opt/airflow/dags/bigC_1.py for tasks to queue
[2025-01-19T14:35:56.733+0000] {logging_mixin.py:188} INFO - [2025-01-19T14:35:56.733+0000] {dagbag.py:540} INFO - Filling up the DagBag from /opt/airflow/dags/bigC_1.py
[2025-01-19T14:35:56.734+0000] {logging_mixin.py:188} INFO - [2025-01-19T14:35:56.734+0000] {dagbag.py:350} ERROR - Failed to import: /opt/airflow/dags/bigC_1.py
Traceback (most recent call last):
  File "/home/airflow/.local/lib/python3.9/site-packages/airflow/models/dagbag.py", line 346, in parse
    loader.exec_module(new_module)
  File "<frozen importlib._bootstrap_external>", line 846, in exec_module
  File "<frozen importlib._bootstrap_external>", line 983, in get_code
  File "<frozen importlib._bootstrap_external>", line 913, in source_to_code
  File "<frozen importlib._bootstrap>", line 228, in _call_with_frames_removed
  File "/opt/airflow/dags/bigC_1.py", line 1
    rom airflow import DAG
        ^
SyntaxError: invalid syntax
[2025-01-19T14:35:56.734+0000] {processor.py:842} WARNING - No viable dags retrieved from /opt/airflow/dags/bigC_1.py
[2025-01-19T14:35:56.744+0000] {processor.py:183} INFO - Processing /opt/airflow/dags/bigC_1.py took 0.017 seconds
[2025-01-19T14:36:27.449+0000] {processor.py:161} INFO - Started process (PID=89927) to work on /opt/airflow/dags/bigC_1.py
[2025-01-19T14:36:27.450+0000] {processor.py:830} INFO - Processing file /opt/airflow/dags/bigC_1.py for tasks to queue
[2025-01-19T14:36:27.451+0000] {logging_mixin.py:188} INFO - [2025-01-19T14:36:27.451+0000] {dagbag.py:540} INFO - Filling up the DagBag from /opt/airflow/dags/bigC_1.py
[2025-01-19T14:36:27.452+0000] {logging_mixin.py:188} INFO - [2025-01-19T14:36:27.452+0000] {dagbag.py:350} ERROR - Failed to import: /opt/airflow/dags/bigC_1.py
Traceback (most recent call last):
  File "/home/airflow/.local/lib/python3.9/site-packages/airflow/models/dagbag.py", line 346, in parse
    loader.exec_module(new_module)
  File "<frozen importlib._bootstrap_external>", line 846, in exec_module
  File "<frozen importlib._bootstrap_external>", line 983, in get_code
  File "<frozen importlib._bootstrap_external>", line 913, in source_to_code
  File "<frozen importlib._bootstrap>", line 228, in _call_with_frames_removed
  File "/opt/airflow/dags/bigC_1.py", line 1
    rom airflow import DAG
        ^
SyntaxError: invalid syntax
[2025-01-19T14:36:27.453+0000] {processor.py:842} WARNING - No viable dags retrieved from /opt/airflow/dags/bigC_1.py
[2025-01-19T14:36:27.463+0000] {processor.py:183} INFO - Processing /opt/airflow/dags/bigC_1.py took 0.017 seconds
[2025-01-19T14:36:57.817+0000] {processor.py:161} INFO - Started process (PID=90056) to work on /opt/airflow/dags/bigC_1.py
[2025-01-19T14:36:57.819+0000] {processor.py:830} INFO - Processing file /opt/airflow/dags/bigC_1.py for tasks to queue
[2025-01-19T14:36:57.819+0000] {logging_mixin.py:188} INFO - [2025-01-19T14:36:57.819+0000] {dagbag.py:540} INFO - Filling up the DagBag from /opt/airflow/dags/bigC_1.py
[2025-01-19T14:36:57.821+0000] {logging_mixin.py:188} INFO - [2025-01-19T14:36:57.820+0000] {dagbag.py:350} ERROR - Failed to import: /opt/airflow/dags/bigC_1.py
Traceback (most recent call last):
  File "/home/airflow/.local/lib/python3.9/site-packages/airflow/models/dagbag.py", line 346, in parse
    loader.exec_module(new_module)
  File "<frozen importlib._bootstrap_external>", line 846, in exec_module
  File "<frozen importlib._bootstrap_external>", line 983, in get_code
  File "<frozen importlib._bootstrap_external>", line 913, in source_to_code
  File "<frozen importlib._bootstrap>", line 228, in _call_with_frames_removed
  File "/opt/airflow/dags/bigC_1.py", line 1
    rom airflow import DAG
        ^
SyntaxError: invalid syntax
[2025-01-19T14:36:57.821+0000] {processor.py:842} WARNING - No viable dags retrieved from /opt/airflow/dags/bigC_1.py
[2025-01-19T14:36:57.831+0000] {processor.py:183} INFO - Processing /opt/airflow/dags/bigC_1.py took 0.017 seconds
[2025-01-19T14:37:28.098+0000] {processor.py:161} INFO - Started process (PID=90178) to work on /opt/airflow/dags/bigC_1.py
[2025-01-19T14:37:28.099+0000] {processor.py:830} INFO - Processing file /opt/airflow/dags/bigC_1.py for tasks to queue
[2025-01-19T14:37:28.100+0000] {logging_mixin.py:188} INFO - [2025-01-19T14:37:28.099+0000] {dagbag.py:540} INFO - Filling up the DagBag from /opt/airflow/dags/bigC_1.py
[2025-01-19T14:37:28.101+0000] {logging_mixin.py:188} INFO - [2025-01-19T14:37:28.100+0000] {dagbag.py:350} ERROR - Failed to import: /opt/airflow/dags/bigC_1.py
Traceback (most recent call last):
  File "/home/airflow/.local/lib/python3.9/site-packages/airflow/models/dagbag.py", line 346, in parse
    loader.exec_module(new_module)
  File "<frozen importlib._bootstrap_external>", line 846, in exec_module
  File "<frozen importlib._bootstrap_external>", line 983, in get_code
  File "<frozen importlib._bootstrap_external>", line 913, in source_to_code
  File "<frozen importlib._bootstrap>", line 228, in _call_with_frames_removed
  File "/opt/airflow/dags/bigC_1.py", line 1
    rom airflow import DAG
        ^
SyntaxError: invalid syntax
[2025-01-19T14:37:28.101+0000] {processor.py:842} WARNING - No viable dags retrieved from /opt/airflow/dags/bigC_1.py
[2025-01-19T14:37:28.112+0000] {processor.py:183} INFO - Processing /opt/airflow/dags/bigC_1.py took 0.018 seconds
[2025-01-19T14:37:58.639+0000] {processor.py:161} INFO - Started process (PID=90307) to work on /opt/airflow/dags/bigC_1.py
[2025-01-19T14:37:58.639+0000] {processor.py:830} INFO - Processing file /opt/airflow/dags/bigC_1.py for tasks to queue
[2025-01-19T14:37:58.640+0000] {logging_mixin.py:188} INFO - [2025-01-19T14:37:58.640+0000] {dagbag.py:540} INFO - Filling up the DagBag from /opt/airflow/dags/bigC_1.py
[2025-01-19T14:37:58.642+0000] {logging_mixin.py:188} INFO - [2025-01-19T14:37:58.641+0000] {dagbag.py:350} ERROR - Failed to import: /opt/airflow/dags/bigC_1.py
Traceback (most recent call last):
  File "/home/airflow/.local/lib/python3.9/site-packages/airflow/models/dagbag.py", line 346, in parse
    loader.exec_module(new_module)
  File "<frozen importlib._bootstrap_external>", line 846, in exec_module
  File "<frozen importlib._bootstrap_external>", line 983, in get_code
  File "<frozen importlib._bootstrap_external>", line 913, in source_to_code
  File "<frozen importlib._bootstrap>", line 228, in _call_with_frames_removed
  File "/opt/airflow/dags/bigC_1.py", line 1
    rom airflow import DAG
        ^
SyntaxError: invalid syntax
[2025-01-19T14:37:58.642+0000] {processor.py:842} WARNING - No viable dags retrieved from /opt/airflow/dags/bigC_1.py
[2025-01-19T14:37:58.653+0000] {processor.py:183} INFO - Processing /opt/airflow/dags/bigC_1.py took 0.017 seconds
[2025-01-19T14:38:25.985+0000] {processor.py:161} INFO - Started process (PID=90429) to work on /opt/airflow/dags/bigC_1.py
[2025-01-19T14:38:25.986+0000] {processor.py:830} INFO - Processing file /opt/airflow/dags/bigC_1.py for tasks to queue
[2025-01-19T14:38:25.987+0000] {logging_mixin.py:188} INFO - [2025-01-19T14:38:25.987+0000] {dagbag.py:540} INFO - Filling up the DagBag from /opt/airflow/dags/bigC_1.py
[2025-01-19T14:38:25.988+0000] {logging_mixin.py:188} INFO - [2025-01-19T14:38:25.988+0000] {dagbag.py:350} ERROR - Failed to import: /opt/airflow/dags/bigC_1.py
Traceback (most recent call last):
  File "/home/airflow/.local/lib/python3.9/site-packages/airflow/models/dagbag.py", line 346, in parse
    loader.exec_module(new_module)
  File "<frozen importlib._bootstrap_external>", line 846, in exec_module
  File "<frozen importlib._bootstrap_external>", line 983, in get_code
  File "<frozen importlib._bootstrap_external>", line 913, in source_to_code
  File "<frozen importlib._bootstrap>", line 228, in _call_with_frames_removed
  File "/opt/airflow/dags/bigC_1.py", line 1
    rom airflow import DAG
        ^
SyntaxError: invalid syntax
[2025-01-19T14:38:25.988+0000] {processor.py:842} WARNING - No viable dags retrieved from /opt/airflow/dags/bigC_1.py
[2025-01-19T14:38:25.999+0000] {processor.py:183} INFO - Processing /opt/airflow/dags/bigC_1.py took 0.018 seconds
[2025-01-19T14:38:56.424+0000] {processor.py:161} INFO - Started process (PID=90558) to work on /opt/airflow/dags/bigC_1.py
[2025-01-19T14:38:56.425+0000] {processor.py:830} INFO - Processing file /opt/airflow/dags/bigC_1.py for tasks to queue
[2025-01-19T14:38:56.426+0000] {logging_mixin.py:188} INFO - [2025-01-19T14:38:56.426+0000] {dagbag.py:540} INFO - Filling up the DagBag from /opt/airflow/dags/bigC_1.py
[2025-01-19T14:38:56.427+0000] {logging_mixin.py:188} INFO - [2025-01-19T14:38:56.427+0000] {dagbag.py:350} ERROR - Failed to import: /opt/airflow/dags/bigC_1.py
Traceback (most recent call last):
  File "/home/airflow/.local/lib/python3.9/site-packages/airflow/models/dagbag.py", line 346, in parse
    loader.exec_module(new_module)
  File "<frozen importlib._bootstrap_external>", line 846, in exec_module
  File "<frozen importlib._bootstrap_external>", line 983, in get_code
  File "<frozen importlib._bootstrap_external>", line 913, in source_to_code
  File "<frozen importlib._bootstrap>", line 228, in _call_with_frames_removed
  File "/opt/airflow/dags/bigC_1.py", line 1
    rom airflow import DAG
        ^
SyntaxError: invalid syntax
[2025-01-19T14:38:56.427+0000] {processor.py:842} WARNING - No viable dags retrieved from /opt/airflow/dags/bigC_1.py
[2025-01-19T14:38:56.437+0000] {processor.py:183} INFO - Processing /opt/airflow/dags/bigC_1.py took 0.017 seconds
[2025-01-19T14:39:26.861+0000] {processor.py:161} INFO - Started process (PID=90687) to work on /opt/airflow/dags/bigC_1.py
[2025-01-19T14:39:26.861+0000] {processor.py:830} INFO - Processing file /opt/airflow/dags/bigC_1.py for tasks to queue
[2025-01-19T14:39:26.862+0000] {logging_mixin.py:188} INFO - [2025-01-19T14:39:26.862+0000] {dagbag.py:540} INFO - Filling up the DagBag from /opt/airflow/dags/bigC_1.py
[2025-01-19T14:39:26.864+0000] {logging_mixin.py:188} INFO - [2025-01-19T14:39:26.863+0000] {dagbag.py:350} ERROR - Failed to import: /opt/airflow/dags/bigC_1.py
Traceback (most recent call last):
  File "/home/airflow/.local/lib/python3.9/site-packages/airflow/models/dagbag.py", line 346, in parse
    loader.exec_module(new_module)
  File "<frozen importlib._bootstrap_external>", line 846, in exec_module
  File "<frozen importlib._bootstrap_external>", line 983, in get_code
  File "<frozen importlib._bootstrap_external>", line 913, in source_to_code
  File "<frozen importlib._bootstrap>", line 228, in _call_with_frames_removed
  File "/opt/airflow/dags/bigC_1.py", line 1
    rom airflow import DAG
        ^
SyntaxError: invalid syntax
[2025-01-19T14:39:26.864+0000] {processor.py:842} WARNING - No viable dags retrieved from /opt/airflow/dags/bigC_1.py
[2025-01-19T14:39:26.874+0000] {processor.py:183} INFO - Processing /opt/airflow/dags/bigC_1.py took 0.016 seconds
[2025-01-19T14:39:37.648+0000] {processor.py:161} INFO - Started process (PID=90741) to work on /opt/airflow/dags/bigC_1.py
[2025-01-19T14:39:37.649+0000] {processor.py:830} INFO - Processing file /opt/airflow/dags/bigC_1.py for tasks to queue
[2025-01-19T14:39:37.650+0000] {logging_mixin.py:188} INFO - [2025-01-19T14:39:37.650+0000] {dagbag.py:540} INFO - Filling up the DagBag from /opt/airflow/dags/bigC_1.py
[2025-01-19T14:39:37.651+0000] {logging_mixin.py:188} INFO - [2025-01-19T14:39:37.651+0000] {dagbag.py:350} ERROR - Failed to import: /opt/airflow/dags/bigC_1.py
Traceback (most recent call last):
  File "/home/airflow/.local/lib/python3.9/site-packages/airflow/models/dagbag.py", line 346, in parse
    loader.exec_module(new_module)
  File "<frozen importlib._bootstrap_external>", line 846, in exec_module
  File "<frozen importlib._bootstrap_external>", line 983, in get_code
  File "<frozen importlib._bootstrap_external>", line 913, in source_to_code
  File "<frozen importlib._bootstrap>", line 228, in _call_with_frames_removed
  File "/opt/airflow/dags/bigC_1.py", line 1
    rom airflow import DAG
        ^
SyntaxError: invalid syntax
[2025-01-19T14:39:37.651+0000] {processor.py:842} WARNING - No viable dags retrieved from /opt/airflow/dags/bigC_1.py
[2025-01-19T14:39:37.662+0000] {processor.py:183} INFO - Processing /opt/airflow/dags/bigC_1.py took 0.016 seconds
[2025-01-19T14:40:07.970+0000] {processor.py:161} INFO - Started process (PID=90863) to work on /opt/airflow/dags/bigC_1.py
[2025-01-19T14:40:07.971+0000] {processor.py:830} INFO - Processing file /opt/airflow/dags/bigC_1.py for tasks to queue
[2025-01-19T14:40:07.972+0000] {logging_mixin.py:188} INFO - [2025-01-19T14:40:07.972+0000] {dagbag.py:540} INFO - Filling up the DagBag from /opt/airflow/dags/bigC_1.py
[2025-01-19T14:40:07.974+0000] {logging_mixin.py:188} INFO - [2025-01-19T14:40:07.973+0000] {dagbag.py:350} ERROR - Failed to import: /opt/airflow/dags/bigC_1.py
Traceback (most recent call last):
  File "/home/airflow/.local/lib/python3.9/site-packages/airflow/models/dagbag.py", line 346, in parse
    loader.exec_module(new_module)
  File "<frozen importlib._bootstrap_external>", line 846, in exec_module
  File "<frozen importlib._bootstrap_external>", line 983, in get_code
  File "<frozen importlib._bootstrap_external>", line 913, in source_to_code
  File "<frozen importlib._bootstrap>", line 228, in _call_with_frames_removed
  File "/opt/airflow/dags/bigC_1.py", line 1
    rom airflow import DAG
        ^
SyntaxError: invalid syntax
[2025-01-19T14:40:07.974+0000] {processor.py:842} WARNING - No viable dags retrieved from /opt/airflow/dags/bigC_1.py
[2025-01-19T14:40:07.984+0000] {processor.py:183} INFO - Processing /opt/airflow/dags/bigC_1.py took 0.018 seconds
[2025-01-19T14:40:30.947+0000] {processor.py:161} INFO - Started process (PID=90943) to work on /opt/airflow/dags/bigC_1.py
[2025-01-19T14:40:30.949+0000] {processor.py:830} INFO - Processing file /opt/airflow/dags/bigC_1.py for tasks to queue
[2025-01-19T14:40:30.949+0000] {logging_mixin.py:188} INFO - [2025-01-19T14:40:30.949+0000] {dagbag.py:540} INFO - Filling up the DagBag from /opt/airflow/dags/bigC_1.py
[2025-01-19T14:40:30.995+0000] {logging_mixin.py:188} INFO - [2025-01-19T14:40:30.994+0000] {dagbag.py:350} ERROR - Failed to import: /opt/airflow/dags/bigC_1.py
Traceback (most recent call last):
  File "/home/airflow/.local/lib/python3.9/site-packages/airflow/models/dagbag.py", line 346, in parse
    loader.exec_module(new_module)
  File "<frozen importlib._bootstrap_external>", line 850, in exec_module
  File "<frozen importlib._bootstrap>", line 228, in _call_with_frames_removed
  File "/opt/airflow/dags/bigC_1.py", line 245, in <module>
    start >> [create_storage_task, create_table_task] >> empty1
  File "/home/airflow/.local/lib/python3.9/site-packages/airflow/models/taskmixin.py", line 104, in __rshift__
    self.set_downstream(other)
  File "/home/airflow/.local/lib/python3.9/site-packages/airflow/models/taskmixin.py", line 262, in set_downstream
    self._set_relatives(task_or_task_list, upstream=False, edge_modifier=edge_modifier)
  File "/home/airflow/.local/lib/python3.9/site-packages/airflow/models/taskmixin.py", line 232, in _set_relatives
    raise AirflowException(
airflow.exceptions.AirflowException: Tried to create relationships between tasks that don't have DAGs yet. Set the DAG for at least one task and try again: [<Task(EmptyOperator): start>, <Task(PythonOperator): create_storage>, <Task(PythonOperator): create_table>]
[2025-01-19T14:40:30.995+0000] {processor.py:842} WARNING - No viable dags retrieved from /opt/airflow/dags/bigC_1.py
[2025-01-19T14:40:31.006+0000] {processor.py:183} INFO - Processing /opt/airflow/dags/bigC_1.py took 0.062 seconds
[2025-01-19T14:41:01.605+0000] {processor.py:161} INFO - Started process (PID=91072) to work on /opt/airflow/dags/bigC_1.py
[2025-01-19T14:41:01.606+0000] {processor.py:830} INFO - Processing file /opt/airflow/dags/bigC_1.py for tasks to queue
[2025-01-19T14:41:01.607+0000] {logging_mixin.py:188} INFO - [2025-01-19T14:41:01.607+0000] {dagbag.py:540} INFO - Filling up the DagBag from /opt/airflow/dags/bigC_1.py
[2025-01-19T14:41:01.651+0000] {logging_mixin.py:188} INFO - [2025-01-19T14:41:01.650+0000] {dagbag.py:350} ERROR - Failed to import: /opt/airflow/dags/bigC_1.py
Traceback (most recent call last):
  File "/home/airflow/.local/lib/python3.9/site-packages/airflow/models/dagbag.py", line 346, in parse
    loader.exec_module(new_module)
  File "<frozen importlib._bootstrap_external>", line 850, in exec_module
  File "<frozen importlib._bootstrap>", line 228, in _call_with_frames_removed
  File "/opt/airflow/dags/bigC_1.py", line 245, in <module>
    start >> [create_storage_task, create_table_task] >> empty1
  File "/home/airflow/.local/lib/python3.9/site-packages/airflow/models/taskmixin.py", line 104, in __rshift__
    self.set_downstream(other)
  File "/home/airflow/.local/lib/python3.9/site-packages/airflow/models/taskmixin.py", line 262, in set_downstream
    self._set_relatives(task_or_task_list, upstream=False, edge_modifier=edge_modifier)
  File "/home/airflow/.local/lib/python3.9/site-packages/airflow/models/taskmixin.py", line 232, in _set_relatives
    raise AirflowException(
airflow.exceptions.AirflowException: Tried to create relationships between tasks that don't have DAGs yet. Set the DAG for at least one task and try again: [<Task(EmptyOperator): start>, <Task(PythonOperator): create_storage>, <Task(PythonOperator): create_table>]
[2025-01-19T14:41:01.651+0000] {processor.py:842} WARNING - No viable dags retrieved from /opt/airflow/dags/bigC_1.py
[2025-01-19T14:41:01.662+0000] {processor.py:183} INFO - Processing /opt/airflow/dags/bigC_1.py took 0.060 seconds
[2025-01-19T14:41:32.381+0000] {processor.py:161} INFO - Started process (PID=91194) to work on /opt/airflow/dags/bigC_1.py
[2025-01-19T14:41:32.382+0000] {processor.py:830} INFO - Processing file /opt/airflow/dags/bigC_1.py for tasks to queue
[2025-01-19T14:41:32.384+0000] {logging_mixin.py:188} INFO - [2025-01-19T14:41:32.383+0000] {dagbag.py:540} INFO - Filling up the DagBag from /opt/airflow/dags/bigC_1.py
[2025-01-19T14:41:32.428+0000] {logging_mixin.py:188} INFO - [2025-01-19T14:41:32.427+0000] {dagbag.py:350} ERROR - Failed to import: /opt/airflow/dags/bigC_1.py
Traceback (most recent call last):
  File "/home/airflow/.local/lib/python3.9/site-packages/airflow/models/dagbag.py", line 346, in parse
    loader.exec_module(new_module)
  File "<frozen importlib._bootstrap_external>", line 850, in exec_module
  File "<frozen importlib._bootstrap>", line 228, in _call_with_frames_removed
  File "/opt/airflow/dags/bigC_1.py", line 245, in <module>
    start >> [create_storage_task, create_table_task] >> empty1
  File "/home/airflow/.local/lib/python3.9/site-packages/airflow/models/taskmixin.py", line 104, in __rshift__
    self.set_downstream(other)
  File "/home/airflow/.local/lib/python3.9/site-packages/airflow/models/taskmixin.py", line 262, in set_downstream
    self._set_relatives(task_or_task_list, upstream=False, edge_modifier=edge_modifier)
  File "/home/airflow/.local/lib/python3.9/site-packages/airflow/models/taskmixin.py", line 232, in _set_relatives
    raise AirflowException(
airflow.exceptions.AirflowException: Tried to create relationships between tasks that don't have DAGs yet. Set the DAG for at least one task and try again: [<Task(EmptyOperator): start>, <Task(PythonOperator): create_storage>, <Task(PythonOperator): create_table>]
[2025-01-19T14:41:32.428+0000] {processor.py:842} WARNING - No viable dags retrieved from /opt/airflow/dags/bigC_1.py
[2025-01-19T14:41:32.438+0000] {processor.py:183} INFO - Processing /opt/airflow/dags/bigC_1.py took 0.060 seconds
[2025-01-19T14:42:03.169+0000] {processor.py:161} INFO - Started process (PID=91323) to work on /opt/airflow/dags/bigC_1.py
[2025-01-19T14:42:03.171+0000] {processor.py:830} INFO - Processing file /opt/airflow/dags/bigC_1.py for tasks to queue
[2025-01-19T14:42:03.172+0000] {logging_mixin.py:188} INFO - [2025-01-19T14:42:03.172+0000] {dagbag.py:540} INFO - Filling up the DagBag from /opt/airflow/dags/bigC_1.py
[2025-01-19T14:42:03.216+0000] {logging_mixin.py:188} INFO - [2025-01-19T14:42:03.215+0000] {dagbag.py:350} ERROR - Failed to import: /opt/airflow/dags/bigC_1.py
Traceback (most recent call last):
  File "/home/airflow/.local/lib/python3.9/site-packages/airflow/models/dagbag.py", line 346, in parse
    loader.exec_module(new_module)
  File "<frozen importlib._bootstrap_external>", line 850, in exec_module
  File "<frozen importlib._bootstrap>", line 228, in _call_with_frames_removed
  File "/opt/airflow/dags/bigC_1.py", line 245, in <module>
    start >> [create_storage_task, create_table_task] >> empty1
  File "/home/airflow/.local/lib/python3.9/site-packages/airflow/models/taskmixin.py", line 104, in __rshift__
    self.set_downstream(other)
  File "/home/airflow/.local/lib/python3.9/site-packages/airflow/models/taskmixin.py", line 262, in set_downstream
    self._set_relatives(task_or_task_list, upstream=False, edge_modifier=edge_modifier)
  File "/home/airflow/.local/lib/python3.9/site-packages/airflow/models/taskmixin.py", line 232, in _set_relatives
    raise AirflowException(
airflow.exceptions.AirflowException: Tried to create relationships between tasks that don't have DAGs yet. Set the DAG for at least one task and try again: [<Task(EmptyOperator): start>, <Task(PythonOperator): create_storage>, <Task(PythonOperator): create_table>]
[2025-01-19T14:42:03.216+0000] {processor.py:842} WARNING - No viable dags retrieved from /opt/airflow/dags/bigC_1.py
[2025-01-19T14:42:03.226+0000] {processor.py:183} INFO - Processing /opt/airflow/dags/bigC_1.py took 0.060 seconds
[2025-01-19T14:42:10.856+0000] {processor.py:161} INFO - Started process (PID=91377) to work on /opt/airflow/dags/bigC_1.py
[2025-01-19T14:42:10.857+0000] {processor.py:830} INFO - Processing file /opt/airflow/dags/bigC_1.py for tasks to queue
[2025-01-19T14:42:10.858+0000] {logging_mixin.py:188} INFO - [2025-01-19T14:42:10.858+0000] {dagbag.py:540} INFO - Filling up the DagBag from /opt/airflow/dags/bigC_1.py
[2025-01-19T14:42:10.902+0000] {logging_mixin.py:188} INFO - [2025-01-19T14:42:10.902+0000] {dagbag.py:350} ERROR - Failed to import: /opt/airflow/dags/bigC_1.py
Traceback (most recent call last):
  File "/home/airflow/.local/lib/python3.9/site-packages/airflow/models/dagbag.py", line 346, in parse
    loader.exec_module(new_module)
  File "<frozen importlib._bootstrap_external>", line 850, in exec_module
  File "<frozen importlib._bootstrap>", line 228, in _call_with_frames_removed
  File "/opt/airflow/dags/bigC_1.py", line 239, in <module>
    start >> [create_storage_task, create_table_task] >> empty1
  File "/home/airflow/.local/lib/python3.9/site-packages/airflow/models/taskmixin.py", line 104, in __rshift__
    self.set_downstream(other)
  File "/home/airflow/.local/lib/python3.9/site-packages/airflow/models/taskmixin.py", line 262, in set_downstream
    self._set_relatives(task_or_task_list, upstream=False, edge_modifier=edge_modifier)
  File "/home/airflow/.local/lib/python3.9/site-packages/airflow/models/taskmixin.py", line 232, in _set_relatives
    raise AirflowException(
airflow.exceptions.AirflowException: Tried to create relationships between tasks that don't have DAGs yet. Set the DAG for at least one task and try again: [<Task(EmptyOperator): start>, <Task(PythonOperator): create_storage>, <Task(PythonOperator): create_table>]
[2025-01-19T14:42:10.902+0000] {processor.py:842} WARNING - No viable dags retrieved from /opt/airflow/dags/bigC_1.py
[2025-01-19T14:42:10.912+0000] {processor.py:183} INFO - Processing /opt/airflow/dags/bigC_1.py took 0.060 seconds
[2025-01-19T14:42:41.717+0000] {processor.py:161} INFO - Started process (PID=91505) to work on /opt/airflow/dags/bigC_1.py
[2025-01-19T14:42:41.718+0000] {processor.py:830} INFO - Processing file /opt/airflow/dags/bigC_1.py for tasks to queue
[2025-01-19T14:42:41.719+0000] {logging_mixin.py:188} INFO - [2025-01-19T14:42:41.719+0000] {dagbag.py:540} INFO - Filling up the DagBag from /opt/airflow/dags/bigC_1.py
[2025-01-19T14:42:41.763+0000] {logging_mixin.py:188} INFO - [2025-01-19T14:42:41.763+0000] {dagbag.py:350} ERROR - Failed to import: /opt/airflow/dags/bigC_1.py
Traceback (most recent call last):
  File "/home/airflow/.local/lib/python3.9/site-packages/airflow/models/dagbag.py", line 346, in parse
    loader.exec_module(new_module)
  File "<frozen importlib._bootstrap_external>", line 850, in exec_module
  File "<frozen importlib._bootstrap>", line 228, in _call_with_frames_removed
  File "/opt/airflow/dags/bigC_1.py", line 239, in <module>
    start >> [create_storage_task, create_table_task] >> empty1
  File "/home/airflow/.local/lib/python3.9/site-packages/airflow/models/taskmixin.py", line 104, in __rshift__
    self.set_downstream(other)
  File "/home/airflow/.local/lib/python3.9/site-packages/airflow/models/taskmixin.py", line 262, in set_downstream
    self._set_relatives(task_or_task_list, upstream=False, edge_modifier=edge_modifier)
  File "/home/airflow/.local/lib/python3.9/site-packages/airflow/models/taskmixin.py", line 232, in _set_relatives
    raise AirflowException(
airflow.exceptions.AirflowException: Tried to create relationships between tasks that don't have DAGs yet. Set the DAG for at least one task and try again: [<Task(EmptyOperator): start>, <Task(PythonOperator): create_storage>, <Task(PythonOperator): create_table>]
[2025-01-19T14:42:41.763+0000] {processor.py:842} WARNING - No viable dags retrieved from /opt/airflow/dags/bigC_1.py
[2025-01-19T14:42:41.773+0000] {processor.py:183} INFO - Processing /opt/airflow/dags/bigC_1.py took 0.060 seconds
[2025-01-19T14:43:12.548+0000] {processor.py:161} INFO - Started process (PID=91628) to work on /opt/airflow/dags/bigC_1.py
[2025-01-19T14:43:12.549+0000] {processor.py:830} INFO - Processing file /opt/airflow/dags/bigC_1.py for tasks to queue
[2025-01-19T14:43:12.550+0000] {logging_mixin.py:188} INFO - [2025-01-19T14:43:12.550+0000] {dagbag.py:540} INFO - Filling up the DagBag from /opt/airflow/dags/bigC_1.py
[2025-01-19T14:43:12.594+0000] {logging_mixin.py:188} INFO - [2025-01-19T14:43:12.594+0000] {dagbag.py:350} ERROR - Failed to import: /opt/airflow/dags/bigC_1.py
Traceback (most recent call last):
  File "/home/airflow/.local/lib/python3.9/site-packages/airflow/models/dagbag.py", line 346, in parse
    loader.exec_module(new_module)
  File "<frozen importlib._bootstrap_external>", line 850, in exec_module
  File "<frozen importlib._bootstrap>", line 228, in _call_with_frames_removed
  File "/opt/airflow/dags/bigC_1.py", line 239, in <module>
    start >> [create_storage_task, create_table_task] >> empty1
  File "/home/airflow/.local/lib/python3.9/site-packages/airflow/models/taskmixin.py", line 104, in __rshift__
    self.set_downstream(other)
  File "/home/airflow/.local/lib/python3.9/site-packages/airflow/models/taskmixin.py", line 262, in set_downstream
    self._set_relatives(task_or_task_list, upstream=False, edge_modifier=edge_modifier)
  File "/home/airflow/.local/lib/python3.9/site-packages/airflow/models/taskmixin.py", line 232, in _set_relatives
    raise AirflowException(
airflow.exceptions.AirflowException: Tried to create relationships between tasks that don't have DAGs yet. Set the DAG for at least one task and try again: [<Task(EmptyOperator): start>, <Task(PythonOperator): create_storage>, <Task(PythonOperator): create_table>]
[2025-01-19T14:43:12.594+0000] {processor.py:842} WARNING - No viable dags retrieved from /opt/airflow/dags/bigC_1.py
[2025-01-19T14:43:12.605+0000] {processor.py:183} INFO - Processing /opt/airflow/dags/bigC_1.py took 0.061 seconds
[2025-01-19T14:43:43.217+0000] {processor.py:161} INFO - Started process (PID=91757) to work on /opt/airflow/dags/bigC_1.py
[2025-01-19T14:43:43.217+0000] {processor.py:830} INFO - Processing file /opt/airflow/dags/bigC_1.py for tasks to queue
[2025-01-19T14:43:43.218+0000] {logging_mixin.py:188} INFO - [2025-01-19T14:43:43.218+0000] {dagbag.py:540} INFO - Filling up the DagBag from /opt/airflow/dags/bigC_1.py
[2025-01-19T14:43:43.262+0000] {logging_mixin.py:188} INFO - [2025-01-19T14:43:43.262+0000] {dagbag.py:350} ERROR - Failed to import: /opt/airflow/dags/bigC_1.py
Traceback (most recent call last):
  File "/home/airflow/.local/lib/python3.9/site-packages/airflow/models/dagbag.py", line 346, in parse
    loader.exec_module(new_module)
  File "<frozen importlib._bootstrap_external>", line 850, in exec_module
  File "<frozen importlib._bootstrap>", line 228, in _call_with_frames_removed
  File "/opt/airflow/dags/bigC_1.py", line 239, in <module>
    start >> [create_storage_task, create_table_task] >> empty1
  File "/home/airflow/.local/lib/python3.9/site-packages/airflow/models/taskmixin.py", line 104, in __rshift__
    self.set_downstream(other)
  File "/home/airflow/.local/lib/python3.9/site-packages/airflow/models/taskmixin.py", line 262, in set_downstream
    self._set_relatives(task_or_task_list, upstream=False, edge_modifier=edge_modifier)
  File "/home/airflow/.local/lib/python3.9/site-packages/airflow/models/taskmixin.py", line 232, in _set_relatives
    raise AirflowException(
airflow.exceptions.AirflowException: Tried to create relationships between tasks that don't have DAGs yet. Set the DAG for at least one task and try again: [<Task(EmptyOperator): start>, <Task(PythonOperator): create_storage>, <Task(PythonOperator): create_table>]
[2025-01-19T14:43:43.262+0000] {processor.py:842} WARNING - No viable dags retrieved from /opt/airflow/dags/bigC_1.py
[2025-01-19T14:43:43.273+0000] {processor.py:183} INFO - Processing /opt/airflow/dags/bigC_1.py took 0.060 seconds
[2025-01-19T14:44:14.061+0000] {processor.py:161} INFO - Started process (PID=91886) to work on /opt/airflow/dags/bigC_1.py
[2025-01-19T14:44:14.062+0000] {processor.py:830} INFO - Processing file /opt/airflow/dags/bigC_1.py for tasks to queue
[2025-01-19T14:44:14.063+0000] {logging_mixin.py:188} INFO - [2025-01-19T14:44:14.063+0000] {dagbag.py:540} INFO - Filling up the DagBag from /opt/airflow/dags/bigC_1.py
[2025-01-19T14:44:14.107+0000] {logging_mixin.py:188} INFO - [2025-01-19T14:44:14.106+0000] {dagbag.py:350} ERROR - Failed to import: /opt/airflow/dags/bigC_1.py
Traceback (most recent call last):
  File "/home/airflow/.local/lib/python3.9/site-packages/airflow/models/dagbag.py", line 346, in parse
    loader.exec_module(new_module)
  File "<frozen importlib._bootstrap_external>", line 850, in exec_module
  File "<frozen importlib._bootstrap>", line 228, in _call_with_frames_removed
  File "/opt/airflow/dags/bigC_1.py", line 239, in <module>
    start >> [create_storage_task, create_table_task] >> empty1
  File "/home/airflow/.local/lib/python3.9/site-packages/airflow/models/taskmixin.py", line 104, in __rshift__
    self.set_downstream(other)
  File "/home/airflow/.local/lib/python3.9/site-packages/airflow/models/taskmixin.py", line 262, in set_downstream
    self._set_relatives(task_or_task_list, upstream=False, edge_modifier=edge_modifier)
  File "/home/airflow/.local/lib/python3.9/site-packages/airflow/models/taskmixin.py", line 232, in _set_relatives
    raise AirflowException(
airflow.exceptions.AirflowException: Tried to create relationships between tasks that don't have DAGs yet. Set the DAG for at least one task and try again: [<Task(EmptyOperator): start>, <Task(PythonOperator): create_storage>, <Task(PythonOperator): create_table>]
[2025-01-19T14:44:14.107+0000] {processor.py:842} WARNING - No viable dags retrieved from /opt/airflow/dags/bigC_1.py
[2025-01-19T14:44:14.117+0000] {processor.py:183} INFO - Processing /opt/airflow/dags/bigC_1.py took 0.060 seconds
[2025-01-19T14:44:44.715+0000] {processor.py:161} INFO - Started process (PID=92008) to work on /opt/airflow/dags/bigC_1.py
[2025-01-19T14:44:44.716+0000] {processor.py:830} INFO - Processing file /opt/airflow/dags/bigC_1.py for tasks to queue
[2025-01-19T14:44:44.717+0000] {logging_mixin.py:188} INFO - [2025-01-19T14:44:44.717+0000] {dagbag.py:540} INFO - Filling up the DagBag from /opt/airflow/dags/bigC_1.py
[2025-01-19T14:44:44.760+0000] {logging_mixin.py:188} INFO - [2025-01-19T14:44:44.760+0000] {dagbag.py:350} ERROR - Failed to import: /opt/airflow/dags/bigC_1.py
Traceback (most recent call last):
  File "/home/airflow/.local/lib/python3.9/site-packages/airflow/models/dagbag.py", line 346, in parse
    loader.exec_module(new_module)
  File "<frozen importlib._bootstrap_external>", line 850, in exec_module
  File "<frozen importlib._bootstrap>", line 228, in _call_with_frames_removed
  File "/opt/airflow/dags/bigC_1.py", line 239, in <module>
    start >> [create_storage_task, create_table_task] >> empty1
  File "/home/airflow/.local/lib/python3.9/site-packages/airflow/models/taskmixin.py", line 104, in __rshift__
    self.set_downstream(other)
  File "/home/airflow/.local/lib/python3.9/site-packages/airflow/models/taskmixin.py", line 262, in set_downstream
    self._set_relatives(task_or_task_list, upstream=False, edge_modifier=edge_modifier)
  File "/home/airflow/.local/lib/python3.9/site-packages/airflow/models/taskmixin.py", line 232, in _set_relatives
    raise AirflowException(
airflow.exceptions.AirflowException: Tried to create relationships between tasks that don't have DAGs yet. Set the DAG for at least one task and try again: [<Task(EmptyOperator): start>, <Task(PythonOperator): create_storage>, <Task(PythonOperator): create_table>]
[2025-01-19T14:44:44.760+0000] {processor.py:842} WARNING - No viable dags retrieved from /opt/airflow/dags/bigC_1.py
[2025-01-19T14:44:44.770+0000] {processor.py:183} INFO - Processing /opt/airflow/dags/bigC_1.py took 0.059 seconds
[2025-01-19T14:45:15.642+0000] {processor.py:161} INFO - Started process (PID=92137) to work on /opt/airflow/dags/bigC_1.py
[2025-01-19T14:45:15.643+0000] {processor.py:830} INFO - Processing file /opt/airflow/dags/bigC_1.py for tasks to queue
[2025-01-19T14:45:15.644+0000] {logging_mixin.py:188} INFO - [2025-01-19T14:45:15.643+0000] {dagbag.py:540} INFO - Filling up the DagBag from /opt/airflow/dags/bigC_1.py
[2025-01-19T14:45:15.686+0000] {logging_mixin.py:188} INFO - [2025-01-19T14:45:15.686+0000] {dagbag.py:350} ERROR - Failed to import: /opt/airflow/dags/bigC_1.py
Traceback (most recent call last):
  File "/home/airflow/.local/lib/python3.9/site-packages/airflow/models/dagbag.py", line 346, in parse
    loader.exec_module(new_module)
  File "<frozen importlib._bootstrap_external>", line 850, in exec_module
  File "<frozen importlib._bootstrap>", line 228, in _call_with_frames_removed
  File "/opt/airflow/dags/bigC_1.py", line 239, in <module>
    start >> [create_storage_task, create_table_task] >> empty1
  File "/home/airflow/.local/lib/python3.9/site-packages/airflow/models/taskmixin.py", line 104, in __rshift__
    self.set_downstream(other)
  File "/home/airflow/.local/lib/python3.9/site-packages/airflow/models/taskmixin.py", line 262, in set_downstream
    self._set_relatives(task_or_task_list, upstream=False, edge_modifier=edge_modifier)
  File "/home/airflow/.local/lib/python3.9/site-packages/airflow/models/taskmixin.py", line 232, in _set_relatives
    raise AirflowException(
airflow.exceptions.AirflowException: Tried to create relationships between tasks that don't have DAGs yet. Set the DAG for at least one task and try again: [<Task(EmptyOperator): start>, <Task(PythonOperator): create_storage>, <Task(PythonOperator): create_table>]
[2025-01-19T14:45:15.687+0000] {processor.py:842} WARNING - No viable dags retrieved from /opt/airflow/dags/bigC_1.py
[2025-01-19T14:45:15.697+0000] {processor.py:183} INFO - Processing /opt/airflow/dags/bigC_1.py took 0.059 seconds
[2025-01-19T14:45:46.012+0000] {processor.py:161} INFO - Started process (PID=92259) to work on /opt/airflow/dags/bigC_1.py
[2025-01-19T14:45:46.014+0000] {processor.py:830} INFO - Processing file /opt/airflow/dags/bigC_1.py for tasks to queue
[2025-01-19T14:45:46.014+0000] {logging_mixin.py:188} INFO - [2025-01-19T14:45:46.014+0000] {dagbag.py:540} INFO - Filling up the DagBag from /opt/airflow/dags/bigC_1.py
[2025-01-19T14:45:46.058+0000] {logging_mixin.py:188} INFO - [2025-01-19T14:45:46.058+0000] {dagbag.py:350} ERROR - Failed to import: /opt/airflow/dags/bigC_1.py
Traceback (most recent call last):
  File "/home/airflow/.local/lib/python3.9/site-packages/airflow/models/dagbag.py", line 346, in parse
    loader.exec_module(new_module)
  File "<frozen importlib._bootstrap_external>", line 850, in exec_module
  File "<frozen importlib._bootstrap>", line 228, in _call_with_frames_removed
  File "/opt/airflow/dags/bigC_1.py", line 239, in <module>
    start >> [create_storage_task, create_table_task] >> empty1
  File "/home/airflow/.local/lib/python3.9/site-packages/airflow/models/taskmixin.py", line 104, in __rshift__
    self.set_downstream(other)
  File "/home/airflow/.local/lib/python3.9/site-packages/airflow/models/taskmixin.py", line 262, in set_downstream
    self._set_relatives(task_or_task_list, upstream=False, edge_modifier=edge_modifier)
  File "/home/airflow/.local/lib/python3.9/site-packages/airflow/models/taskmixin.py", line 232, in _set_relatives
    raise AirflowException(
airflow.exceptions.AirflowException: Tried to create relationships between tasks that don't have DAGs yet. Set the DAG for at least one task and try again: [<Task(EmptyOperator): start>, <Task(PythonOperator): create_storage>, <Task(PythonOperator): create_table>]
[2025-01-19T14:45:46.058+0000] {processor.py:842} WARNING - No viable dags retrieved from /opt/airflow/dags/bigC_1.py
[2025-01-19T14:45:46.068+0000] {processor.py:183} INFO - Processing /opt/airflow/dags/bigC_1.py took 0.060 seconds
[2025-01-19T14:46:16.491+0000] {processor.py:161} INFO - Started process (PID=92388) to work on /opt/airflow/dags/bigC_1.py
[2025-01-19T14:46:16.492+0000] {processor.py:830} INFO - Processing file /opt/airflow/dags/bigC_1.py for tasks to queue
[2025-01-19T14:46:16.492+0000] {logging_mixin.py:188} INFO - [2025-01-19T14:46:16.492+0000] {dagbag.py:540} INFO - Filling up the DagBag from /opt/airflow/dags/bigC_1.py
[2025-01-19T14:46:16.535+0000] {logging_mixin.py:188} INFO - [2025-01-19T14:46:16.535+0000] {dagbag.py:350} ERROR - Failed to import: /opt/airflow/dags/bigC_1.py
Traceback (most recent call last):
  File "/home/airflow/.local/lib/python3.9/site-packages/airflow/models/dagbag.py", line 346, in parse
    loader.exec_module(new_module)
  File "<frozen importlib._bootstrap_external>", line 850, in exec_module
  File "<frozen importlib._bootstrap>", line 228, in _call_with_frames_removed
  File "/opt/airflow/dags/bigC_1.py", line 239, in <module>
    start >> [create_storage_task, create_table_task] >> empty1
  File "/home/airflow/.local/lib/python3.9/site-packages/airflow/models/taskmixin.py", line 104, in __rshift__
    self.set_downstream(other)
  File "/home/airflow/.local/lib/python3.9/site-packages/airflow/models/taskmixin.py", line 262, in set_downstream
    self._set_relatives(task_or_task_list, upstream=False, edge_modifier=edge_modifier)
  File "/home/airflow/.local/lib/python3.9/site-packages/airflow/models/taskmixin.py", line 232, in _set_relatives
    raise AirflowException(
airflow.exceptions.AirflowException: Tried to create relationships between tasks that don't have DAGs yet. Set the DAG for at least one task and try again: [<Task(EmptyOperator): start>, <Task(PythonOperator): create_storage>, <Task(PythonOperator): create_table>]
[2025-01-19T14:46:16.535+0000] {processor.py:842} WARNING - No viable dags retrieved from /opt/airflow/dags/bigC_1.py
[2025-01-19T14:46:16.546+0000] {processor.py:183} INFO - Processing /opt/airflow/dags/bigC_1.py took 0.058 seconds
[2025-01-19T14:46:47.118+0000] {processor.py:161} INFO - Started process (PID=92517) to work on /opt/airflow/dags/bigC_1.py
[2025-01-19T14:46:47.120+0000] {processor.py:830} INFO - Processing file /opt/airflow/dags/bigC_1.py for tasks to queue
[2025-01-19T14:46:47.120+0000] {logging_mixin.py:188} INFO - [2025-01-19T14:46:47.120+0000] {dagbag.py:540} INFO - Filling up the DagBag from /opt/airflow/dags/bigC_1.py
[2025-01-19T14:46:47.165+0000] {logging_mixin.py:188} INFO - [2025-01-19T14:46:47.165+0000] {dagbag.py:350} ERROR - Failed to import: /opt/airflow/dags/bigC_1.py
Traceback (most recent call last):
  File "/home/airflow/.local/lib/python3.9/site-packages/airflow/models/dagbag.py", line 346, in parse
    loader.exec_module(new_module)
  File "<frozen importlib._bootstrap_external>", line 850, in exec_module
  File "<frozen importlib._bootstrap>", line 228, in _call_with_frames_removed
  File "/opt/airflow/dags/bigC_1.py", line 239, in <module>
    start >> [create_storage_task, create_table_task] >> empty1
  File "/home/airflow/.local/lib/python3.9/site-packages/airflow/models/taskmixin.py", line 104, in __rshift__
    self.set_downstream(other)
  File "/home/airflow/.local/lib/python3.9/site-packages/airflow/models/taskmixin.py", line 262, in set_downstream
    self._set_relatives(task_or_task_list, upstream=False, edge_modifier=edge_modifier)
  File "/home/airflow/.local/lib/python3.9/site-packages/airflow/models/taskmixin.py", line 232, in _set_relatives
    raise AirflowException(
airflow.exceptions.AirflowException: Tried to create relationships between tasks that don't have DAGs yet. Set the DAG for at least one task and try again: [<Task(EmptyOperator): start>, <Task(PythonOperator): create_storage>, <Task(PythonOperator): create_table>]
[2025-01-19T14:46:47.165+0000] {processor.py:842} WARNING - No viable dags retrieved from /opt/airflow/dags/bigC_1.py
[2025-01-19T14:46:47.177+0000] {processor.py:183} INFO - Processing /opt/airflow/dags/bigC_1.py took 0.062 seconds
[2025-01-19T14:47:17.557+0000] {processor.py:161} INFO - Started process (PID=92639) to work on /opt/airflow/dags/bigC_1.py
[2025-01-19T14:47:17.558+0000] {processor.py:830} INFO - Processing file /opt/airflow/dags/bigC_1.py for tasks to queue
[2025-01-19T14:47:17.558+0000] {logging_mixin.py:188} INFO - [2025-01-19T14:47:17.558+0000] {dagbag.py:540} INFO - Filling up the DagBag from /opt/airflow/dags/bigC_1.py
[2025-01-19T14:47:17.601+0000] {logging_mixin.py:188} INFO - [2025-01-19T14:47:17.601+0000] {dagbag.py:350} ERROR - Failed to import: /opt/airflow/dags/bigC_1.py
Traceback (most recent call last):
  File "/home/airflow/.local/lib/python3.9/site-packages/airflow/models/dagbag.py", line 346, in parse
    loader.exec_module(new_module)
  File "<frozen importlib._bootstrap_external>", line 850, in exec_module
  File "<frozen importlib._bootstrap>", line 228, in _call_with_frames_removed
  File "/opt/airflow/dags/bigC_1.py", line 239, in <module>
    start >> [create_storage_task, create_table_task] >> empty1
  File "/home/airflow/.local/lib/python3.9/site-packages/airflow/models/taskmixin.py", line 104, in __rshift__
    self.set_downstream(other)
  File "/home/airflow/.local/lib/python3.9/site-packages/airflow/models/taskmixin.py", line 262, in set_downstream
    self._set_relatives(task_or_task_list, upstream=False, edge_modifier=edge_modifier)
  File "/home/airflow/.local/lib/python3.9/site-packages/airflow/models/taskmixin.py", line 232, in _set_relatives
    raise AirflowException(
airflow.exceptions.AirflowException: Tried to create relationships between tasks that don't have DAGs yet. Set the DAG for at least one task and try again: [<Task(EmptyOperator): start>, <Task(PythonOperator): create_storage>, <Task(PythonOperator): create_table>]
[2025-01-19T14:47:17.601+0000] {processor.py:842} WARNING - No viable dags retrieved from /opt/airflow/dags/bigC_1.py
[2025-01-19T14:47:17.611+0000] {processor.py:183} INFO - Processing /opt/airflow/dags/bigC_1.py took 0.058 seconds
[2025-01-19T14:47:47.968+0000] {processor.py:161} INFO - Started process (PID=92768) to work on /opt/airflow/dags/bigC_1.py
[2025-01-19T14:47:47.969+0000] {processor.py:830} INFO - Processing file /opt/airflow/dags/bigC_1.py for tasks to queue
[2025-01-19T14:47:47.970+0000] {logging_mixin.py:188} INFO - [2025-01-19T14:47:47.970+0000] {dagbag.py:540} INFO - Filling up the DagBag from /opt/airflow/dags/bigC_1.py
[2025-01-19T14:47:48.103+0000] {logging_mixin.py:188} INFO - [2025-01-19T14:47:48.102+0000] {dagbag.py:350} ERROR - Failed to import: /opt/airflow/dags/bigC_1.py
Traceback (most recent call last):
  File "/home/airflow/.local/lib/python3.9/site-packages/airflow/models/dagbag.py", line 346, in parse
    loader.exec_module(new_module)
  File "<frozen importlib._bootstrap_external>", line 850, in exec_module
  File "<frozen importlib._bootstrap>", line 228, in _call_with_frames_removed
  File "/opt/airflow/dags/bigC_1.py", line 239, in <module>
    start >> [create_storage_task, create_table_task] >> empty1
  File "/home/airflow/.local/lib/python3.9/site-packages/airflow/models/taskmixin.py", line 104, in __rshift__
    self.set_downstream(other)
  File "/home/airflow/.local/lib/python3.9/site-packages/airflow/models/taskmixin.py", line 262, in set_downstream
    self._set_relatives(task_or_task_list, upstream=False, edge_modifier=edge_modifier)
  File "/home/airflow/.local/lib/python3.9/site-packages/airflow/models/taskmixin.py", line 232, in _set_relatives
    raise AirflowException(
airflow.exceptions.AirflowException: Tried to create relationships between tasks that don't have DAGs yet. Set the DAG for at least one task and try again: [<Task(EmptyOperator): start>, <Task(PythonOperator): create_storage>, <Task(PythonOperator): create_table>]
[2025-01-19T14:47:48.103+0000] {processor.py:842} WARNING - No viable dags retrieved from /opt/airflow/dags/bigC_1.py
[2025-01-19T14:47:48.112+0000] {processor.py:183} INFO - Processing /opt/airflow/dags/bigC_1.py took 0.148 seconds
[2025-01-19T14:48:18.462+0000] {processor.py:161} INFO - Started process (PID=92897) to work on /opt/airflow/dags/bigC_1.py
[2025-01-19T14:48:18.463+0000] {processor.py:830} INFO - Processing file /opt/airflow/dags/bigC_1.py for tasks to queue
[2025-01-19T14:48:18.464+0000] {logging_mixin.py:188} INFO - [2025-01-19T14:48:18.464+0000] {dagbag.py:540} INFO - Filling up the DagBag from /opt/airflow/dags/bigC_1.py
[2025-01-19T14:48:18.596+0000] {logging_mixin.py:188} INFO - [2025-01-19T14:48:18.595+0000] {dagbag.py:350} ERROR - Failed to import: /opt/airflow/dags/bigC_1.py
Traceback (most recent call last):
  File "/home/airflow/.local/lib/python3.9/site-packages/airflow/models/dagbag.py", line 346, in parse
    loader.exec_module(new_module)
  File "<frozen importlib._bootstrap_external>", line 850, in exec_module
  File "<frozen importlib._bootstrap>", line 228, in _call_with_frames_removed
  File "/opt/airflow/dags/bigC_1.py", line 239, in <module>
    start >> [create_storage_task, create_table_task] >> empty1
  File "/home/airflow/.local/lib/python3.9/site-packages/airflow/models/taskmixin.py", line 104, in __rshift__
    self.set_downstream(other)
  File "/home/airflow/.local/lib/python3.9/site-packages/airflow/models/taskmixin.py", line 262, in set_downstream
    self._set_relatives(task_or_task_list, upstream=False, edge_modifier=edge_modifier)
  File "/home/airflow/.local/lib/python3.9/site-packages/airflow/models/taskmixin.py", line 232, in _set_relatives
    raise AirflowException(
airflow.exceptions.AirflowException: Tried to create relationships between tasks that don't have DAGs yet. Set the DAG for at least one task and try again: [<Task(EmptyOperator): start>, <Task(PythonOperator): create_storage>, <Task(PythonOperator): create_table>]
[2025-01-19T14:48:18.596+0000] {processor.py:842} WARNING - No viable dags retrieved from /opt/airflow/dags/bigC_1.py
[2025-01-19T14:48:18.606+0000] {processor.py:183} INFO - Processing /opt/airflow/dags/bigC_1.py took 0.147 seconds
[2025-01-19T14:48:48.776+0000] {processor.py:161} INFO - Started process (PID=93019) to work on /opt/airflow/dags/bigC_1.py
[2025-01-19T14:48:48.777+0000] {processor.py:830} INFO - Processing file /opt/airflow/dags/bigC_1.py for tasks to queue
[2025-01-19T14:48:48.778+0000] {logging_mixin.py:188} INFO - [2025-01-19T14:48:48.777+0000] {dagbag.py:540} INFO - Filling up the DagBag from /opt/airflow/dags/bigC_1.py
[2025-01-19T14:48:48.820+0000] {logging_mixin.py:188} INFO - [2025-01-19T14:48:48.819+0000] {dagbag.py:350} ERROR - Failed to import: /opt/airflow/dags/bigC_1.py
Traceback (most recent call last):
  File "/home/airflow/.local/lib/python3.9/site-packages/airflow/models/dagbag.py", line 346, in parse
    loader.exec_module(new_module)
  File "<frozen importlib._bootstrap_external>", line 850, in exec_module
  File "<frozen importlib._bootstrap>", line 228, in _call_with_frames_removed
  File "/opt/airflow/dags/bigC_1.py", line 239, in <module>
    start >> [create_storage_task, create_table_task] >> empty1
  File "/home/airflow/.local/lib/python3.9/site-packages/airflow/models/taskmixin.py", line 104, in __rshift__
    self.set_downstream(other)
  File "/home/airflow/.local/lib/python3.9/site-packages/airflow/models/taskmixin.py", line 262, in set_downstream
    self._set_relatives(task_or_task_list, upstream=False, edge_modifier=edge_modifier)
  File "/home/airflow/.local/lib/python3.9/site-packages/airflow/models/taskmixin.py", line 232, in _set_relatives
    raise AirflowException(
airflow.exceptions.AirflowException: Tried to create relationships between tasks that don't have DAGs yet. Set the DAG for at least one task and try again: [<Task(EmptyOperator): start>, <Task(PythonOperator): create_storage>, <Task(PythonOperator): create_table>]
[2025-01-19T14:48:48.820+0000] {processor.py:842} WARNING - No viable dags retrieved from /opt/airflow/dags/bigC_1.py
[2025-01-19T14:48:48.830+0000] {processor.py:183} INFO - Processing /opt/airflow/dags/bigC_1.py took 0.058 seconds
[2025-01-19T14:49:19.440+0000] {processor.py:161} INFO - Started process (PID=93148) to work on /opt/airflow/dags/bigC_1.py
[2025-01-19T14:49:19.441+0000] {processor.py:830} INFO - Processing file /opt/airflow/dags/bigC_1.py for tasks to queue
[2025-01-19T14:49:19.442+0000] {logging_mixin.py:188} INFO - [2025-01-19T14:49:19.442+0000] {dagbag.py:540} INFO - Filling up the DagBag from /opt/airflow/dags/bigC_1.py
[2025-01-19T14:49:19.485+0000] {logging_mixin.py:188} INFO - [2025-01-19T14:49:19.485+0000] {dagbag.py:350} ERROR - Failed to import: /opt/airflow/dags/bigC_1.py
Traceback (most recent call last):
  File "/home/airflow/.local/lib/python3.9/site-packages/airflow/models/dagbag.py", line 346, in parse
    loader.exec_module(new_module)
  File "<frozen importlib._bootstrap_external>", line 850, in exec_module
  File "<frozen importlib._bootstrap>", line 228, in _call_with_frames_removed
  File "/opt/airflow/dags/bigC_1.py", line 239, in <module>
    start >> [create_storage_task, create_table_task] >> empty1
  File "/home/airflow/.local/lib/python3.9/site-packages/airflow/models/taskmixin.py", line 104, in __rshift__
    self.set_downstream(other)
  File "/home/airflow/.local/lib/python3.9/site-packages/airflow/models/taskmixin.py", line 262, in set_downstream
    self._set_relatives(task_or_task_list, upstream=False, edge_modifier=edge_modifier)
  File "/home/airflow/.local/lib/python3.9/site-packages/airflow/models/taskmixin.py", line 232, in _set_relatives
    raise AirflowException(
airflow.exceptions.AirflowException: Tried to create relationships between tasks that don't have DAGs yet. Set the DAG for at least one task and try again: [<Task(EmptyOperator): start>, <Task(PythonOperator): create_storage>, <Task(PythonOperator): create_table>]
[2025-01-19T14:49:19.485+0000] {processor.py:842} WARNING - No viable dags retrieved from /opt/airflow/dags/bigC_1.py
[2025-01-19T14:49:19.495+0000] {processor.py:183} INFO - Processing /opt/airflow/dags/bigC_1.py took 0.059 seconds
[2025-01-19T14:49:49.860+0000] {processor.py:161} INFO - Started process (PID=93277) to work on /opt/airflow/dags/bigC_1.py
[2025-01-19T14:49:49.861+0000] {processor.py:830} INFO - Processing file /opt/airflow/dags/bigC_1.py for tasks to queue
[2025-01-19T14:49:49.862+0000] {logging_mixin.py:188} INFO - [2025-01-19T14:49:49.861+0000] {dagbag.py:540} INFO - Filling up the DagBag from /opt/airflow/dags/bigC_1.py
[2025-01-19T14:49:49.904+0000] {logging_mixin.py:188} INFO - [2025-01-19T14:49:49.904+0000] {dagbag.py:350} ERROR - Failed to import: /opt/airflow/dags/bigC_1.py
Traceback (most recent call last):
  File "/home/airflow/.local/lib/python3.9/site-packages/airflow/models/dagbag.py", line 346, in parse
    loader.exec_module(new_module)
  File "<frozen importlib._bootstrap_external>", line 850, in exec_module
  File "<frozen importlib._bootstrap>", line 228, in _call_with_frames_removed
  File "/opt/airflow/dags/bigC_1.py", line 239, in <module>
    start >> [create_storage_task, create_table_task] >> empty1
  File "/home/airflow/.local/lib/python3.9/site-packages/airflow/models/taskmixin.py", line 104, in __rshift__
    self.set_downstream(other)
  File "/home/airflow/.local/lib/python3.9/site-packages/airflow/models/taskmixin.py", line 262, in set_downstream
    self._set_relatives(task_or_task_list, upstream=False, edge_modifier=edge_modifier)
  File "/home/airflow/.local/lib/python3.9/site-packages/airflow/models/taskmixin.py", line 232, in _set_relatives
    raise AirflowException(
airflow.exceptions.AirflowException: Tried to create relationships between tasks that don't have DAGs yet. Set the DAG for at least one task and try again: [<Task(EmptyOperator): start>, <Task(PythonOperator): create_storage>, <Task(PythonOperator): create_table>]
[2025-01-19T14:49:49.904+0000] {processor.py:842} WARNING - No viable dags retrieved from /opt/airflow/dags/bigC_1.py
[2025-01-19T14:49:49.914+0000] {processor.py:183} INFO - Processing /opt/airflow/dags/bigC_1.py took 0.058 seconds
[2025-01-19T14:50:20.268+0000] {processor.py:161} INFO - Started process (PID=93399) to work on /opt/airflow/dags/bigC_1.py
[2025-01-19T14:50:20.269+0000] {processor.py:830} INFO - Processing file /opt/airflow/dags/bigC_1.py for tasks to queue
[2025-01-19T14:50:20.270+0000] {logging_mixin.py:188} INFO - [2025-01-19T14:50:20.270+0000] {dagbag.py:540} INFO - Filling up the DagBag from /opt/airflow/dags/bigC_1.py
[2025-01-19T14:50:20.316+0000] {logging_mixin.py:188} INFO - [2025-01-19T14:50:20.315+0000] {dagbag.py:350} ERROR - Failed to import: /opt/airflow/dags/bigC_1.py
Traceback (most recent call last):
  File "/home/airflow/.local/lib/python3.9/site-packages/airflow/models/dagbag.py", line 346, in parse
    loader.exec_module(new_module)
  File "<frozen importlib._bootstrap_external>", line 850, in exec_module
  File "<frozen importlib._bootstrap>", line 228, in _call_with_frames_removed
  File "/opt/airflow/dags/bigC_1.py", line 239, in <module>
    start >> [create_storage_task, create_table_task] >> empty1
  File "/home/airflow/.local/lib/python3.9/site-packages/airflow/models/taskmixin.py", line 104, in __rshift__
    self.set_downstream(other)
  File "/home/airflow/.local/lib/python3.9/site-packages/airflow/models/taskmixin.py", line 262, in set_downstream
    self._set_relatives(task_or_task_list, upstream=False, edge_modifier=edge_modifier)
  File "/home/airflow/.local/lib/python3.9/site-packages/airflow/models/taskmixin.py", line 232, in _set_relatives
    raise AirflowException(
airflow.exceptions.AirflowException: Tried to create relationships between tasks that don't have DAGs yet. Set the DAG for at least one task and try again: [<Task(EmptyOperator): start>, <Task(PythonOperator): create_storage>, <Task(PythonOperator): create_table>]
[2025-01-19T14:50:20.316+0000] {processor.py:842} WARNING - No viable dags retrieved from /opt/airflow/dags/bigC_1.py
[2025-01-19T14:50:20.326+0000] {processor.py:183} INFO - Processing /opt/airflow/dags/bigC_1.py took 0.062 seconds
[2025-01-19T14:50:50.842+0000] {processor.py:161} INFO - Started process (PID=93527) to work on /opt/airflow/dags/bigC_1.py
[2025-01-19T14:50:50.843+0000] {processor.py:830} INFO - Processing file /opt/airflow/dags/bigC_1.py for tasks to queue
[2025-01-19T14:50:50.844+0000] {logging_mixin.py:188} INFO - [2025-01-19T14:50:50.844+0000] {dagbag.py:540} INFO - Filling up the DagBag from /opt/airflow/dags/bigC_1.py
[2025-01-19T14:50:50.887+0000] {logging_mixin.py:188} INFO - [2025-01-19T14:50:50.887+0000] {dagbag.py:350} ERROR - Failed to import: /opt/airflow/dags/bigC_1.py
Traceback (most recent call last):
  File "/home/airflow/.local/lib/python3.9/site-packages/airflow/models/dagbag.py", line 346, in parse
    loader.exec_module(new_module)
  File "<frozen importlib._bootstrap_external>", line 850, in exec_module
  File "<frozen importlib._bootstrap>", line 228, in _call_with_frames_removed
  File "/opt/airflow/dags/bigC_1.py", line 239, in <module>
    start >> [create_storage_task, create_table_task] >> empty1
  File "/home/airflow/.local/lib/python3.9/site-packages/airflow/models/taskmixin.py", line 104, in __rshift__
    self.set_downstream(other)
  File "/home/airflow/.local/lib/python3.9/site-packages/airflow/models/taskmixin.py", line 262, in set_downstream
    self._set_relatives(task_or_task_list, upstream=False, edge_modifier=edge_modifier)
  File "/home/airflow/.local/lib/python3.9/site-packages/airflow/models/taskmixin.py", line 232, in _set_relatives
    raise AirflowException(
airflow.exceptions.AirflowException: Tried to create relationships between tasks that don't have DAGs yet. Set the DAG for at least one task and try again: [<Task(EmptyOperator): start>, <Task(PythonOperator): create_storage>, <Task(PythonOperator): create_table>]
[2025-01-19T14:50:50.888+0000] {processor.py:842} WARNING - No viable dags retrieved from /opt/airflow/dags/bigC_1.py
[2025-01-19T14:50:50.898+0000] {processor.py:183} INFO - Processing /opt/airflow/dags/bigC_1.py took 0.059 seconds
[2025-01-19T14:51:11.679+0000] {processor.py:161} INFO - Started process (PID=93607) to work on /opt/airflow/dags/bigC_1.py
[2025-01-19T14:51:11.680+0000] {processor.py:830} INFO - Processing file /opt/airflow/dags/bigC_1.py for tasks to queue
[2025-01-19T14:51:11.681+0000] {logging_mixin.py:188} INFO - [2025-01-19T14:51:11.681+0000] {dagbag.py:540} INFO - Filling up the DagBag from /opt/airflow/dags/bigC_1.py
[2025-01-19T14:51:11.790+0000] {logging_mixin.py:188} INFO - [2025-01-19T14:51:11.789+0000] {dagbag.py:350} ERROR - Failed to import: /opt/airflow/dags/bigC_1.py
Traceback (most recent call last):
  File "/home/airflow/.local/lib/python3.9/site-packages/airflow/models/dagbag.py", line 346, in parse
    loader.exec_module(new_module)
  File "<frozen importlib._bootstrap_external>", line 850, in exec_module
  File "<frozen importlib._bootstrap>", line 228, in _call_with_frames_removed
  File "/opt/airflow/dags/bigC_1.py", line 242, in <module>
    start >> [create_storage_task, create_table_task] >> empty1
  File "/home/airflow/.local/lib/python3.9/site-packages/airflow/models/taskmixin.py", line 104, in __rshift__
    self.set_downstream(other)
  File "/home/airflow/.local/lib/python3.9/site-packages/airflow/models/taskmixin.py", line 262, in set_downstream
    self._set_relatives(task_or_task_list, upstream=False, edge_modifier=edge_modifier)
  File "/home/airflow/.local/lib/python3.9/site-packages/airflow/models/taskmixin.py", line 232, in _set_relatives
    raise AirflowException(
airflow.exceptions.AirflowException: Tried to create relationships between tasks that don't have DAGs yet. Set the DAG for at least one task and try again: [<Task(EmptyOperator): start>, <Task(PythonOperator): create_storage>, <Task(PythonOperator): create_table>]
[2025-01-19T14:51:11.790+0000] {processor.py:842} WARNING - No viable dags retrieved from /opt/airflow/dags/bigC_1.py
[2025-01-19T14:51:11.800+0000] {processor.py:183} INFO - Processing /opt/airflow/dags/bigC_1.py took 0.125 seconds
[2025-01-19T14:51:42.454+0000] {processor.py:161} INFO - Started process (PID=93729) to work on /opt/airflow/dags/bigC_1.py
[2025-01-19T14:51:42.455+0000] {processor.py:830} INFO - Processing file /opt/airflow/dags/bigC_1.py for tasks to queue
[2025-01-19T14:51:42.456+0000] {logging_mixin.py:188} INFO - [2025-01-19T14:51:42.456+0000] {dagbag.py:540} INFO - Filling up the DagBag from /opt/airflow/dags/bigC_1.py
[2025-01-19T14:51:42.565+0000] {logging_mixin.py:188} INFO - [2025-01-19T14:51:42.564+0000] {dagbag.py:350} ERROR - Failed to import: /opt/airflow/dags/bigC_1.py
Traceback (most recent call last):
  File "/home/airflow/.local/lib/python3.9/site-packages/airflow/models/dagbag.py", line 346, in parse
    loader.exec_module(new_module)
  File "<frozen importlib._bootstrap_external>", line 850, in exec_module
  File "<frozen importlib._bootstrap>", line 228, in _call_with_frames_removed
  File "/opt/airflow/dags/bigC_1.py", line 242, in <module>
    start >> [create_storage_task, create_table_task] >> empty1
  File "/home/airflow/.local/lib/python3.9/site-packages/airflow/models/taskmixin.py", line 104, in __rshift__
    self.set_downstream(other)
  File "/home/airflow/.local/lib/python3.9/site-packages/airflow/models/taskmixin.py", line 262, in set_downstream
    self._set_relatives(task_or_task_list, upstream=False, edge_modifier=edge_modifier)
  File "/home/airflow/.local/lib/python3.9/site-packages/airflow/models/taskmixin.py", line 232, in _set_relatives
    raise AirflowException(
airflow.exceptions.AirflowException: Tried to create relationships between tasks that don't have DAGs yet. Set the DAG for at least one task and try again: [<Task(EmptyOperator): start>, <Task(PythonOperator): create_storage>, <Task(PythonOperator): create_table>]
[2025-01-19T14:51:42.565+0000] {processor.py:842} WARNING - No viable dags retrieved from /opt/airflow/dags/bigC_1.py
[2025-01-19T14:51:42.575+0000] {processor.py:183} INFO - Processing /opt/airflow/dags/bigC_1.py took 0.125 seconds
[2025-01-19T14:52:02.187+0000] {processor.py:161} INFO - Started process (PID=93846) to work on /opt/airflow/dags/bigC_1.py
[2025-01-19T14:52:02.188+0000] {processor.py:830} INFO - Processing file /opt/airflow/dags/bigC_1.py for tasks to queue
[2025-01-19T14:52:02.189+0000] {logging_mixin.py:188} INFO - [2025-01-19T14:52:02.189+0000] {dagbag.py:540} INFO - Filling up the DagBag from /opt/airflow/dags/bigC_1.py
[2025-01-19T14:52:02.299+0000] {logging_mixin.py:188} INFO - [2025-01-19T14:52:02.298+0000] {dagbag.py:350} ERROR - Failed to import: /opt/airflow/dags/bigC_1.py
Traceback (most recent call last):
  File "/home/airflow/.local/lib/python3.9/site-packages/airflow/models/dagbag.py", line 346, in parse
    loader.exec_module(new_module)
  File "<frozen importlib._bootstrap_external>", line 850, in exec_module
  File "<frozen importlib._bootstrap>", line 228, in _call_with_frames_removed
  File "/opt/airflow/dags/bigC_1.py", line 242, in <module>
    start >> [create_storage_task, create_table_task] >> empty1
  File "/home/airflow/.local/lib/python3.9/site-packages/airflow/models/taskmixin.py", line 104, in __rshift__
    self.set_downstream(other)
  File "/home/airflow/.local/lib/python3.9/site-packages/airflow/models/taskmixin.py", line 262, in set_downstream
    self._set_relatives(task_or_task_list, upstream=False, edge_modifier=edge_modifier)
  File "/home/airflow/.local/lib/python3.9/site-packages/airflow/models/taskmixin.py", line 232, in _set_relatives
    raise AirflowException(
airflow.exceptions.AirflowException: Tried to create relationships between tasks that don't have DAGs yet. Set the DAG for at least one task and try again: [<Task(EmptyOperator): start>, <Task(PythonOperator): create_storage>, <Task(PythonOperator): create_table>]
[2025-01-19T14:52:02.299+0000] {processor.py:842} WARNING - No viable dags retrieved from /opt/airflow/dags/bigC_1.py
[2025-01-19T14:52:02.309+0000] {processor.py:183} INFO - Processing /opt/airflow/dags/bigC_1.py took 0.126 seconds
[2025-01-19T14:52:32.871+0000] {processor.py:161} INFO - Started process (PID=93975) to work on /opt/airflow/dags/bigC_1.py
[2025-01-19T14:52:32.872+0000] {processor.py:830} INFO - Processing file /opt/airflow/dags/bigC_1.py for tasks to queue
[2025-01-19T14:52:32.873+0000] {logging_mixin.py:188} INFO - [2025-01-19T14:52:32.873+0000] {dagbag.py:540} INFO - Filling up the DagBag from /opt/airflow/dags/bigC_1.py
[2025-01-19T14:52:32.980+0000] {logging_mixin.py:188} INFO - [2025-01-19T14:52:32.980+0000] {dagbag.py:350} ERROR - Failed to import: /opt/airflow/dags/bigC_1.py
Traceback (most recent call last):
  File "/home/airflow/.local/lib/python3.9/site-packages/airflow/models/dagbag.py", line 346, in parse
    loader.exec_module(new_module)
  File "<frozen importlib._bootstrap_external>", line 850, in exec_module
  File "<frozen importlib._bootstrap>", line 228, in _call_with_frames_removed
  File "/opt/airflow/dags/bigC_1.py", line 242, in <module>
    start >> [create_storage_task, create_table_task] >> empty1
  File "/home/airflow/.local/lib/python3.9/site-packages/airflow/models/taskmixin.py", line 104, in __rshift__
    self.set_downstream(other)
  File "/home/airflow/.local/lib/python3.9/site-packages/airflow/models/taskmixin.py", line 262, in set_downstream
    self._set_relatives(task_or_task_list, upstream=False, edge_modifier=edge_modifier)
  File "/home/airflow/.local/lib/python3.9/site-packages/airflow/models/taskmixin.py", line 232, in _set_relatives
    raise AirflowException(
airflow.exceptions.AirflowException: Tried to create relationships between tasks that don't have DAGs yet. Set the DAG for at least one task and try again: [<Task(EmptyOperator): start>, <Task(PythonOperator): create_storage>, <Task(PythonOperator): create_table>]
[2025-01-19T14:52:32.980+0000] {processor.py:842} WARNING - No viable dags retrieved from /opt/airflow/dags/bigC_1.py
[2025-01-19T14:52:32.989+0000] {processor.py:183} INFO - Processing /opt/airflow/dags/bigC_1.py took 0.123 seconds
[2025-01-19T14:53:02.750+0000] {processor.py:161} INFO - Started process (PID=94097) to work on /opt/airflow/dags/bigC_1.py
[2025-01-19T14:53:02.751+0000] {processor.py:830} INFO - Processing file /opt/airflow/dags/bigC_1.py for tasks to queue
[2025-01-19T14:53:02.752+0000] {logging_mixin.py:188} INFO - [2025-01-19T14:53:02.751+0000] {dagbag.py:540} INFO - Filling up the DagBag from /opt/airflow/dags/bigC_1.py
[2025-01-19T14:53:02.859+0000] {logging_mixin.py:188} INFO - [2025-01-19T14:53:02.858+0000] {dagbag.py:350} ERROR - Failed to import: /opt/airflow/dags/bigC_1.py
Traceback (most recent call last):
  File "/home/airflow/.local/lib/python3.9/site-packages/airflow/models/dagbag.py", line 346, in parse
    loader.exec_module(new_module)
  File "<frozen importlib._bootstrap_external>", line 850, in exec_module
  File "<frozen importlib._bootstrap>", line 228, in _call_with_frames_removed
  File "/opt/airflow/dags/bigC_1.py", line 242, in <module>
    start >> [create_storage_task, create_table_task] >> empty1
  File "/home/airflow/.local/lib/python3.9/site-packages/airflow/models/taskmixin.py", line 104, in __rshift__
    self.set_downstream(other)
  File "/home/airflow/.local/lib/python3.9/site-packages/airflow/models/taskmixin.py", line 262, in set_downstream
    self._set_relatives(task_or_task_list, upstream=False, edge_modifier=edge_modifier)
  File "/home/airflow/.local/lib/python3.9/site-packages/airflow/models/taskmixin.py", line 232, in _set_relatives
    raise AirflowException(
airflow.exceptions.AirflowException: Tried to create relationships between tasks that don't have DAGs yet. Set the DAG for at least one task and try again: [<Task(EmptyOperator): start>, <Task(PythonOperator): create_storage>, <Task(PythonOperator): create_table>]
[2025-01-19T14:53:02.859+0000] {processor.py:842} WARNING - No viable dags retrieved from /opt/airflow/dags/bigC_1.py
[2025-01-19T14:53:02.869+0000] {processor.py:183} INFO - Processing /opt/airflow/dags/bigC_1.py took 0.123 seconds
[2025-01-19T14:53:33.044+0000] {processor.py:161} INFO - Started process (PID=94211) to work on /opt/airflow/dags/bigC_1.py
[2025-01-19T14:53:33.045+0000] {processor.py:830} INFO - Processing file /opt/airflow/dags/bigC_1.py for tasks to queue
[2025-01-19T14:53:33.046+0000] {logging_mixin.py:188} INFO - [2025-01-19T14:53:33.045+0000] {dagbag.py:540} INFO - Filling up the DagBag from /opt/airflow/dags/bigC_1.py
[2025-01-19T14:53:33.155+0000] {logging_mixin.py:188} INFO - [2025-01-19T14:53:33.155+0000] {dagbag.py:350} ERROR - Failed to import: /opt/airflow/dags/bigC_1.py
Traceback (most recent call last):
  File "/home/airflow/.local/lib/python3.9/site-packages/airflow/models/dagbag.py", line 346, in parse
    loader.exec_module(new_module)
  File "<frozen importlib._bootstrap_external>", line 850, in exec_module
  File "<frozen importlib._bootstrap>", line 228, in _call_with_frames_removed
  File "/opt/airflow/dags/bigC_1.py", line 242, in <module>
    start >> [create_storage_task, create_table_task] >> empty1
  File "/home/airflow/.local/lib/python3.9/site-packages/airflow/models/taskmixin.py", line 104, in __rshift__
    self.set_downstream(other)
  File "/home/airflow/.local/lib/python3.9/site-packages/airflow/models/taskmixin.py", line 262, in set_downstream
    self._set_relatives(task_or_task_list, upstream=False, edge_modifier=edge_modifier)
  File "/home/airflow/.local/lib/python3.9/site-packages/airflow/models/taskmixin.py", line 232, in _set_relatives
    raise AirflowException(
airflow.exceptions.AirflowException: Tried to create relationships between tasks that don't have DAGs yet. Set the DAG for at least one task and try again: [<Task(EmptyOperator): start>, <Task(PythonOperator): create_storage>, <Task(PythonOperator): create_table>]
[2025-01-19T14:53:33.155+0000] {processor.py:842} WARNING - No viable dags retrieved from /opt/airflow/dags/bigC_1.py
[2025-01-19T14:53:33.166+0000] {processor.py:183} INFO - Processing /opt/airflow/dags/bigC_1.py took 0.126 seconds
[2025-01-19T14:54:03.827+0000] {processor.py:161} INFO - Started process (PID=94340) to work on /opt/airflow/dags/bigC_1.py
[2025-01-19T14:54:03.828+0000] {processor.py:830} INFO - Processing file /opt/airflow/dags/bigC_1.py for tasks to queue
[2025-01-19T14:54:03.829+0000] {logging_mixin.py:188} INFO - [2025-01-19T14:54:03.828+0000] {dagbag.py:540} INFO - Filling up the DagBag from /opt/airflow/dags/bigC_1.py
[2025-01-19T14:54:03.937+0000] {logging_mixin.py:188} INFO - [2025-01-19T14:54:03.937+0000] {dagbag.py:350} ERROR - Failed to import: /opt/airflow/dags/bigC_1.py
Traceback (most recent call last):
  File "/home/airflow/.local/lib/python3.9/site-packages/airflow/models/dagbag.py", line 346, in parse
    loader.exec_module(new_module)
  File "<frozen importlib._bootstrap_external>", line 850, in exec_module
  File "<frozen importlib._bootstrap>", line 228, in _call_with_frames_removed
  File "/opt/airflow/dags/bigC_1.py", line 242, in <module>
    start >> [create_storage_task, create_table_task] >> empty1
  File "/home/airflow/.local/lib/python3.9/site-packages/airflow/models/taskmixin.py", line 104, in __rshift__
    self.set_downstream(other)
  File "/home/airflow/.local/lib/python3.9/site-packages/airflow/models/taskmixin.py", line 262, in set_downstream
    self._set_relatives(task_or_task_list, upstream=False, edge_modifier=edge_modifier)
  File "/home/airflow/.local/lib/python3.9/site-packages/airflow/models/taskmixin.py", line 232, in _set_relatives
    raise AirflowException(
airflow.exceptions.AirflowException: Tried to create relationships between tasks that don't have DAGs yet. Set the DAG for at least one task and try again: [<Task(EmptyOperator): start>, <Task(PythonOperator): create_storage>, <Task(PythonOperator): create_table>]
[2025-01-19T14:54:03.938+0000] {processor.py:842} WARNING - No viable dags retrieved from /opt/airflow/dags/bigC_1.py
[2025-01-19T14:54:03.950+0000] {processor.py:183} INFO - Processing /opt/airflow/dags/bigC_1.py took 0.127 seconds
[2025-01-19T14:54:34.439+0000] {processor.py:161} INFO - Started process (PID=94462) to work on /opt/airflow/dags/bigC_1.py
[2025-01-19T14:54:34.441+0000] {processor.py:830} INFO - Processing file /opt/airflow/dags/bigC_1.py for tasks to queue
[2025-01-19T14:54:34.442+0000] {logging_mixin.py:188} INFO - [2025-01-19T14:54:34.442+0000] {dagbag.py:540} INFO - Filling up the DagBag from /opt/airflow/dags/bigC_1.py
[2025-01-19T14:54:34.551+0000] {logging_mixin.py:188} INFO - [2025-01-19T14:54:34.550+0000] {dagbag.py:350} ERROR - Failed to import: /opt/airflow/dags/bigC_1.py
Traceback (most recent call last):
  File "/home/airflow/.local/lib/python3.9/site-packages/airflow/models/dagbag.py", line 346, in parse
    loader.exec_module(new_module)
  File "<frozen importlib._bootstrap_external>", line 850, in exec_module
  File "<frozen importlib._bootstrap>", line 228, in _call_with_frames_removed
  File "/opt/airflow/dags/bigC_1.py", line 242, in <module>
    start >> [create_storage_task, create_table_task] >> empty1
  File "/home/airflow/.local/lib/python3.9/site-packages/airflow/models/taskmixin.py", line 104, in __rshift__
    self.set_downstream(other)
  File "/home/airflow/.local/lib/python3.9/site-packages/airflow/models/taskmixin.py", line 262, in set_downstream
    self._set_relatives(task_or_task_list, upstream=False, edge_modifier=edge_modifier)
  File "/home/airflow/.local/lib/python3.9/site-packages/airflow/models/taskmixin.py", line 232, in _set_relatives
    raise AirflowException(
airflow.exceptions.AirflowException: Tried to create relationships between tasks that don't have DAGs yet. Set the DAG for at least one task and try again: [<Task(EmptyOperator): start>, <Task(PythonOperator): create_storage>, <Task(PythonOperator): create_table>]
[2025-01-19T14:54:34.551+0000] {processor.py:842} WARNING - No viable dags retrieved from /opt/airflow/dags/bigC_1.py
[2025-01-19T14:54:34.562+0000] {processor.py:183} INFO - Processing /opt/airflow/dags/bigC_1.py took 0.126 seconds
[2025-01-19T14:55:04.731+0000] {processor.py:161} INFO - Started process (PID=94592) to work on /opt/airflow/dags/bigC_1.py
[2025-01-19T14:55:04.732+0000] {processor.py:830} INFO - Processing file /opt/airflow/dags/bigC_1.py for tasks to queue
[2025-01-19T14:55:04.733+0000] {logging_mixin.py:188} INFO - [2025-01-19T14:55:04.732+0000] {dagbag.py:540} INFO - Filling up the DagBag from /opt/airflow/dags/bigC_1.py
[2025-01-19T14:55:04.841+0000] {logging_mixin.py:188} INFO - [2025-01-19T14:55:04.841+0000] {dagbag.py:350} ERROR - Failed to import: /opt/airflow/dags/bigC_1.py
Traceback (most recent call last):
  File "/home/airflow/.local/lib/python3.9/site-packages/airflow/models/dagbag.py", line 346, in parse
    loader.exec_module(new_module)
  File "<frozen importlib._bootstrap_external>", line 850, in exec_module
  File "<frozen importlib._bootstrap>", line 228, in _call_with_frames_removed
  File "/opt/airflow/dags/bigC_1.py", line 242, in <module>
    start >> [create_storage_task, create_table_task] >> empty1
  File "/home/airflow/.local/lib/python3.9/site-packages/airflow/models/taskmixin.py", line 104, in __rshift__
    self.set_downstream(other)
  File "/home/airflow/.local/lib/python3.9/site-packages/airflow/models/taskmixin.py", line 262, in set_downstream
    self._set_relatives(task_or_task_list, upstream=False, edge_modifier=edge_modifier)
  File "/home/airflow/.local/lib/python3.9/site-packages/airflow/models/taskmixin.py", line 232, in _set_relatives
    raise AirflowException(
airflow.exceptions.AirflowException: Tried to create relationships between tasks that don't have DAGs yet. Set the DAG for at least one task and try again: [<Task(EmptyOperator): start>, <Task(PythonOperator): create_storage>, <Task(PythonOperator): create_table>]
[2025-01-19T14:55:04.842+0000] {processor.py:842} WARNING - No viable dags retrieved from /opt/airflow/dags/bigC_1.py
[2025-01-19T14:55:04.855+0000] {processor.py:183} INFO - Processing /opt/airflow/dags/bigC_1.py took 0.127 seconds
[2025-01-19T14:55:35.125+0000] {processor.py:161} INFO - Started process (PID=94721) to work on /opt/airflow/dags/bigC_1.py
[2025-01-19T14:55:35.126+0000] {processor.py:830} INFO - Processing file /opt/airflow/dags/bigC_1.py for tasks to queue
[2025-01-19T14:55:35.127+0000] {logging_mixin.py:188} INFO - [2025-01-19T14:55:35.127+0000] {dagbag.py:540} INFO - Filling up the DagBag from /opt/airflow/dags/bigC_1.py
[2025-01-19T14:55:35.233+0000] {logging_mixin.py:188} INFO - [2025-01-19T14:55:35.233+0000] {dagbag.py:350} ERROR - Failed to import: /opt/airflow/dags/bigC_1.py
Traceback (most recent call last):
  File "/home/airflow/.local/lib/python3.9/site-packages/airflow/models/dagbag.py", line 346, in parse
    loader.exec_module(new_module)
  File "<frozen importlib._bootstrap_external>", line 850, in exec_module
  File "<frozen importlib._bootstrap>", line 228, in _call_with_frames_removed
  File "/opt/airflow/dags/bigC_1.py", line 242, in <module>
    start >> [create_storage_task, create_table_task] >> empty1
  File "/home/airflow/.local/lib/python3.9/site-packages/airflow/models/taskmixin.py", line 104, in __rshift__
    self.set_downstream(other)
  File "/home/airflow/.local/lib/python3.9/site-packages/airflow/models/taskmixin.py", line 262, in set_downstream
    self._set_relatives(task_or_task_list, upstream=False, edge_modifier=edge_modifier)
  File "/home/airflow/.local/lib/python3.9/site-packages/airflow/models/taskmixin.py", line 232, in _set_relatives
    raise AirflowException(
airflow.exceptions.AirflowException: Tried to create relationships between tasks that don't have DAGs yet. Set the DAG for at least one task and try again: [<Task(EmptyOperator): start>, <Task(PythonOperator): create_storage>, <Task(PythonOperator): create_table>]
[2025-01-19T14:55:35.234+0000] {processor.py:842} WARNING - No viable dags retrieved from /opt/airflow/dags/bigC_1.py
[2025-01-19T14:55:35.245+0000] {processor.py:183} INFO - Processing /opt/airflow/dags/bigC_1.py took 0.123 seconds
[2025-01-19T14:56:05.318+0000] {processor.py:161} INFO - Started process (PID=94838) to work on /opt/airflow/dags/bigC_1.py
[2025-01-19T14:56:05.319+0000] {processor.py:830} INFO - Processing file /opt/airflow/dags/bigC_1.py for tasks to queue
[2025-01-19T14:56:05.320+0000] {logging_mixin.py:188} INFO - [2025-01-19T14:56:05.320+0000] {dagbag.py:540} INFO - Filling up the DagBag from /opt/airflow/dags/bigC_1.py
[2025-01-19T14:56:05.513+0000] {logging_mixin.py:188} INFO - [2025-01-19T14:56:05.512+0000] {dagbag.py:350} ERROR - Failed to import: /opt/airflow/dags/bigC_1.py
Traceback (most recent call last):
  File "/home/airflow/.local/lib/python3.9/site-packages/airflow/models/dagbag.py", line 346, in parse
    loader.exec_module(new_module)
  File "<frozen importlib._bootstrap_external>", line 850, in exec_module
  File "<frozen importlib._bootstrap>", line 228, in _call_with_frames_removed
  File "/opt/airflow/dags/bigC_1.py", line 242, in <module>
    start >> [create_storage_task, create_table_task] >> empty1
  File "/home/airflow/.local/lib/python3.9/site-packages/airflow/models/taskmixin.py", line 104, in __rshift__
    self.set_downstream(other)
  File "/home/airflow/.local/lib/python3.9/site-packages/airflow/models/taskmixin.py", line 262, in set_downstream
    self._set_relatives(task_or_task_list, upstream=False, edge_modifier=edge_modifier)
  File "/home/airflow/.local/lib/python3.9/site-packages/airflow/models/taskmixin.py", line 232, in _set_relatives
    raise AirflowException(
airflow.exceptions.AirflowException: Tried to create relationships between tasks that don't have DAGs yet. Set the DAG for at least one task and try again: [<Task(EmptyOperator): start>, <Task(PythonOperator): create_storage>, <Task(PythonOperator): create_table>]
[2025-01-19T14:56:05.513+0000] {processor.py:842} WARNING - No viable dags retrieved from /opt/airflow/dags/bigC_1.py
[2025-01-19T14:56:05.522+0000] {processor.py:183} INFO - Processing /opt/airflow/dags/bigC_1.py took 0.207 seconds
[2025-01-19T14:56:35.599+0000] {processor.py:161} INFO - Started process (PID=94957) to work on /opt/airflow/dags/bigC_1.py
[2025-01-19T14:56:35.600+0000] {processor.py:830} INFO - Processing file /opt/airflow/dags/bigC_1.py for tasks to queue
[2025-01-19T14:56:35.601+0000] {logging_mixin.py:188} INFO - [2025-01-19T14:56:35.601+0000] {dagbag.py:540} INFO - Filling up the DagBag from /opt/airflow/dags/bigC_1.py
[2025-01-19T14:56:35.796+0000] {logging_mixin.py:188} INFO - [2025-01-19T14:56:35.796+0000] {dagbag.py:350} ERROR - Failed to import: /opt/airflow/dags/bigC_1.py
Traceback (most recent call last):
  File "/home/airflow/.local/lib/python3.9/site-packages/airflow/models/dagbag.py", line 346, in parse
    loader.exec_module(new_module)
  File "<frozen importlib._bootstrap_external>", line 850, in exec_module
  File "<frozen importlib._bootstrap>", line 228, in _call_with_frames_removed
  File "/opt/airflow/dags/bigC_1.py", line 242, in <module>
    start >> [create_storage_task, create_table_task] >> empty1
  File "/home/airflow/.local/lib/python3.9/site-packages/airflow/models/taskmixin.py", line 104, in __rshift__
    self.set_downstream(other)
  File "/home/airflow/.local/lib/python3.9/site-packages/airflow/models/taskmixin.py", line 262, in set_downstream
    self._set_relatives(task_or_task_list, upstream=False, edge_modifier=edge_modifier)
  File "/home/airflow/.local/lib/python3.9/site-packages/airflow/models/taskmixin.py", line 232, in _set_relatives
    raise AirflowException(
airflow.exceptions.AirflowException: Tried to create relationships between tasks that don't have DAGs yet. Set the DAG for at least one task and try again: [<Task(EmptyOperator): start>, <Task(PythonOperator): create_storage>, <Task(PythonOperator): create_table>]
[2025-01-19T14:56:35.796+0000] {processor.py:842} WARNING - No viable dags retrieved from /opt/airflow/dags/bigC_1.py
[2025-01-19T14:56:35.808+0000] {processor.py:183} INFO - Processing /opt/airflow/dags/bigC_1.py took 0.213 seconds
[2025-01-19T14:57:06.108+0000] {processor.py:161} INFO - Started process (PID=95086) to work on /opt/airflow/dags/bigC_1.py
[2025-01-19T14:57:06.108+0000] {processor.py:830} INFO - Processing file /opt/airflow/dags/bigC_1.py for tasks to queue
[2025-01-19T14:57:06.110+0000] {logging_mixin.py:188} INFO - [2025-01-19T14:57:06.109+0000] {dagbag.py:540} INFO - Filling up the DagBag from /opt/airflow/dags/bigC_1.py
[2025-01-19T14:57:06.306+0000] {logging_mixin.py:188} INFO - [2025-01-19T14:57:06.306+0000] {dagbag.py:350} ERROR - Failed to import: /opt/airflow/dags/bigC_1.py
Traceback (most recent call last):
  File "/home/airflow/.local/lib/python3.9/site-packages/airflow/models/dagbag.py", line 346, in parse
    loader.exec_module(new_module)
  File "<frozen importlib._bootstrap_external>", line 850, in exec_module
  File "<frozen importlib._bootstrap>", line 228, in _call_with_frames_removed
  File "/opt/airflow/dags/bigC_1.py", line 242, in <module>
    start >> [create_storage_task, create_table_task] >> empty1
  File "/home/airflow/.local/lib/python3.9/site-packages/airflow/models/taskmixin.py", line 104, in __rshift__
    self.set_downstream(other)
  File "/home/airflow/.local/lib/python3.9/site-packages/airflow/models/taskmixin.py", line 262, in set_downstream
    self._set_relatives(task_or_task_list, upstream=False, edge_modifier=edge_modifier)
  File "/home/airflow/.local/lib/python3.9/site-packages/airflow/models/taskmixin.py", line 232, in _set_relatives
    raise AirflowException(
airflow.exceptions.AirflowException: Tried to create relationships between tasks that don't have DAGs yet. Set the DAG for at least one task and try again: [<Task(EmptyOperator): start>, <Task(PythonOperator): create_storage>, <Task(PythonOperator): create_table>]
[2025-01-19T14:57:06.307+0000] {processor.py:842} WARNING - No viable dags retrieved from /opt/airflow/dags/bigC_1.py
[2025-01-19T14:57:06.316+0000] {processor.py:183} INFO - Processing /opt/airflow/dags/bigC_1.py took 0.212 seconds
[2025-01-19T14:57:36.540+0000] {processor.py:161} INFO - Started process (PID=95208) to work on /opt/airflow/dags/bigC_1.py
[2025-01-19T14:57:36.541+0000] {processor.py:830} INFO - Processing file /opt/airflow/dags/bigC_1.py for tasks to queue
[2025-01-19T14:57:36.542+0000] {logging_mixin.py:188} INFO - [2025-01-19T14:57:36.542+0000] {dagbag.py:540} INFO - Filling up the DagBag from /opt/airflow/dags/bigC_1.py
[2025-01-19T14:57:36.738+0000] {logging_mixin.py:188} INFO - [2025-01-19T14:57:36.738+0000] {dagbag.py:350} ERROR - Failed to import: /opt/airflow/dags/bigC_1.py
Traceback (most recent call last):
  File "/home/airflow/.local/lib/python3.9/site-packages/airflow/models/dagbag.py", line 346, in parse
    loader.exec_module(new_module)
  File "<frozen importlib._bootstrap_external>", line 850, in exec_module
  File "<frozen importlib._bootstrap>", line 228, in _call_with_frames_removed
  File "/opt/airflow/dags/bigC_1.py", line 242, in <module>
    start >> [create_storage_task, create_table_task] >> empty1
  File "/home/airflow/.local/lib/python3.9/site-packages/airflow/models/taskmixin.py", line 104, in __rshift__
    self.set_downstream(other)
  File "/home/airflow/.local/lib/python3.9/site-packages/airflow/models/taskmixin.py", line 262, in set_downstream
    self._set_relatives(task_or_task_list, upstream=False, edge_modifier=edge_modifier)
  File "/home/airflow/.local/lib/python3.9/site-packages/airflow/models/taskmixin.py", line 232, in _set_relatives
    raise AirflowException(
airflow.exceptions.AirflowException: Tried to create relationships between tasks that don't have DAGs yet. Set the DAG for at least one task and try again: [<Task(EmptyOperator): start>, <Task(PythonOperator): create_storage>, <Task(PythonOperator): create_table>]
[2025-01-19T14:57:36.738+0000] {processor.py:842} WARNING - No viable dags retrieved from /opt/airflow/dags/bigC_1.py
[2025-01-19T14:57:36.748+0000] {processor.py:183} INFO - Processing /opt/airflow/dags/bigC_1.py took 0.212 seconds
[2025-01-19T14:57:45.615+0000] {processor.py:161} INFO - Started process (PID=95255) to work on /opt/airflow/dags/bigC_1.py
[2025-01-19T14:57:45.616+0000] {processor.py:830} INFO - Processing file /opt/airflow/dags/bigC_1.py for tasks to queue
[2025-01-19T14:57:45.617+0000] {logging_mixin.py:188} INFO - [2025-01-19T14:57:45.617+0000] {dagbag.py:540} INFO - Filling up the DagBag from /opt/airflow/dags/bigC_1.py
[2025-01-19T14:57:45.806+0000] {logging_mixin.py:188} INFO - [2025-01-19T14:57:45.805+0000] {dagbag.py:350} ERROR - Failed to import: /opt/airflow/dags/bigC_1.py
Traceback (most recent call last):
  File "/home/airflow/.local/lib/python3.9/site-packages/airflow/models/dagbag.py", line 346, in parse
    loader.exec_module(new_module)
  File "<frozen importlib._bootstrap_external>", line 850, in exec_module
  File "<frozen importlib._bootstrap>", line 228, in _call_with_frames_removed
  File "/opt/airflow/dags/bigC_1.py", line 245, in <module>
    start >> [create_storage_task, create_table_task] >> empty1
  File "/home/airflow/.local/lib/python3.9/site-packages/airflow/models/taskmixin.py", line 104, in __rshift__
    self.set_downstream(other)
  File "/home/airflow/.local/lib/python3.9/site-packages/airflow/models/taskmixin.py", line 262, in set_downstream
    self._set_relatives(task_or_task_list, upstream=False, edge_modifier=edge_modifier)
  File "/home/airflow/.local/lib/python3.9/site-packages/airflow/models/taskmixin.py", line 232, in _set_relatives
    raise AirflowException(
airflow.exceptions.AirflowException: Tried to create relationships between tasks that don't have DAGs yet. Set the DAG for at least one task and try again: [<Task(EmptyOperator): start>, <Task(PythonOperator): create_storage>, <Task(PythonOperator): create_table>]
[2025-01-19T14:57:45.806+0000] {processor.py:842} WARNING - No viable dags retrieved from /opt/airflow/dags/bigC_1.py
[2025-01-19T14:57:45.816+0000] {processor.py:183} INFO - Processing /opt/airflow/dags/bigC_1.py took 0.204 seconds
[2025-01-19T14:58:16.116+0000] {processor.py:161} INFO - Started process (PID=95384) to work on /opt/airflow/dags/bigC_1.py
[2025-01-19T14:58:16.117+0000] {processor.py:830} INFO - Processing file /opt/airflow/dags/bigC_1.py for tasks to queue
[2025-01-19T14:58:16.118+0000] {logging_mixin.py:188} INFO - [2025-01-19T14:58:16.118+0000] {dagbag.py:540} INFO - Filling up the DagBag from /opt/airflow/dags/bigC_1.py
[2025-01-19T14:58:16.311+0000] {logging_mixin.py:188} INFO - [2025-01-19T14:58:16.310+0000] {dagbag.py:350} ERROR - Failed to import: /opt/airflow/dags/bigC_1.py
Traceback (most recent call last):
  File "/home/airflow/.local/lib/python3.9/site-packages/airflow/models/dagbag.py", line 346, in parse
    loader.exec_module(new_module)
  File "<frozen importlib._bootstrap_external>", line 850, in exec_module
  File "<frozen importlib._bootstrap>", line 228, in _call_with_frames_removed
  File "/opt/airflow/dags/bigC_1.py", line 245, in <module>
    start >> [create_storage_task, create_table_task] >> empty1
  File "/home/airflow/.local/lib/python3.9/site-packages/airflow/models/taskmixin.py", line 104, in __rshift__
    self.set_downstream(other)
  File "/home/airflow/.local/lib/python3.9/site-packages/airflow/models/taskmixin.py", line 262, in set_downstream
    self._set_relatives(task_or_task_list, upstream=False, edge_modifier=edge_modifier)
  File "/home/airflow/.local/lib/python3.9/site-packages/airflow/models/taskmixin.py", line 232, in _set_relatives
    raise AirflowException(
airflow.exceptions.AirflowException: Tried to create relationships between tasks that don't have DAGs yet. Set the DAG for at least one task and try again: [<Task(EmptyOperator): start>, <Task(PythonOperator): create_storage>, <Task(PythonOperator): create_table>]
[2025-01-19T14:58:16.311+0000] {processor.py:842} WARNING - No viable dags retrieved from /opt/airflow/dags/bigC_1.py
[2025-01-19T14:58:16.320+0000] {processor.py:183} INFO - Processing /opt/airflow/dags/bigC_1.py took 0.208 seconds
[2025-01-19T14:58:46.807+0000] {processor.py:161} INFO - Started process (PID=95506) to work on /opt/airflow/dags/bigC_1.py
[2025-01-19T14:58:46.809+0000] {processor.py:830} INFO - Processing file /opt/airflow/dags/bigC_1.py for tasks to queue
[2025-01-19T14:58:46.809+0000] {logging_mixin.py:188} INFO - [2025-01-19T14:58:46.809+0000] {dagbag.py:540} INFO - Filling up the DagBag from /opt/airflow/dags/bigC_1.py
[2025-01-19T14:58:46.919+0000] {logging_mixin.py:188} INFO - [2025-01-19T14:58:46.918+0000] {dagbag.py:350} ERROR - Failed to import: /opt/airflow/dags/bigC_1.py
Traceback (most recent call last):
  File "/home/airflow/.local/lib/python3.9/site-packages/airflow/models/dagbag.py", line 346, in parse
    loader.exec_module(new_module)
  File "<frozen importlib._bootstrap_external>", line 850, in exec_module
  File "<frozen importlib._bootstrap>", line 228, in _call_with_frames_removed
  File "/opt/airflow/dags/bigC_1.py", line 245, in <module>
    start >> [create_storage_task, create_table_task] >> empty1
  File "/home/airflow/.local/lib/python3.9/site-packages/airflow/models/taskmixin.py", line 104, in __rshift__
    self.set_downstream(other)
  File "/home/airflow/.local/lib/python3.9/site-packages/airflow/models/taskmixin.py", line 262, in set_downstream
    self._set_relatives(task_or_task_list, upstream=False, edge_modifier=edge_modifier)
  File "/home/airflow/.local/lib/python3.9/site-packages/airflow/models/taskmixin.py", line 232, in _set_relatives
    raise AirflowException(
airflow.exceptions.AirflowException: Tried to create relationships between tasks that don't have DAGs yet. Set the DAG for at least one task and try again: [<Task(EmptyOperator): start>, <Task(PythonOperator): create_storage>, <Task(PythonOperator): create_table>]
[2025-01-19T14:58:46.919+0000] {processor.py:842} WARNING - No viable dags retrieved from /opt/airflow/dags/bigC_1.py
[2025-01-19T14:58:46.929+0000] {processor.py:183} INFO - Processing /opt/airflow/dags/bigC_1.py took 0.125 seconds
[2025-01-19T14:59:17.013+0000] {processor.py:161} INFO - Started process (PID=95635) to work on /opt/airflow/dags/bigC_1.py
[2025-01-19T14:59:17.014+0000] {processor.py:830} INFO - Processing file /opt/airflow/dags/bigC_1.py for tasks to queue
[2025-01-19T14:59:17.015+0000] {logging_mixin.py:188} INFO - [2025-01-19T14:59:17.015+0000] {dagbag.py:540} INFO - Filling up the DagBag from /opt/airflow/dags/bigC_1.py
[2025-01-19T14:59:17.125+0000] {logging_mixin.py:188} INFO - [2025-01-19T14:59:17.125+0000] {dagbag.py:350} ERROR - Failed to import: /opt/airflow/dags/bigC_1.py
Traceback (most recent call last):
  File "/home/airflow/.local/lib/python3.9/site-packages/airflow/models/dagbag.py", line 346, in parse
    loader.exec_module(new_module)
  File "<frozen importlib._bootstrap_external>", line 850, in exec_module
  File "<frozen importlib._bootstrap>", line 228, in _call_with_frames_removed
  File "/opt/airflow/dags/bigC_1.py", line 245, in <module>
    start >> [create_storage_task, create_table_task] >> empty1
  File "/home/airflow/.local/lib/python3.9/site-packages/airflow/models/taskmixin.py", line 104, in __rshift__
    self.set_downstream(other)
  File "/home/airflow/.local/lib/python3.9/site-packages/airflow/models/taskmixin.py", line 262, in set_downstream
    self._set_relatives(task_or_task_list, upstream=False, edge_modifier=edge_modifier)
  File "/home/airflow/.local/lib/python3.9/site-packages/airflow/models/taskmixin.py", line 232, in _set_relatives
    raise AirflowException(
airflow.exceptions.AirflowException: Tried to create relationships between tasks that don't have DAGs yet. Set the DAG for at least one task and try again: [<Task(EmptyOperator): start>, <Task(PythonOperator): create_storage>, <Task(PythonOperator): create_table>]
[2025-01-19T14:59:17.125+0000] {processor.py:842} WARNING - No viable dags retrieved from /opt/airflow/dags/bigC_1.py
[2025-01-19T14:59:17.135+0000] {processor.py:183} INFO - Processing /opt/airflow/dags/bigC_1.py took 0.126 seconds
[2025-01-19T14:59:47.303+0000] {processor.py:161} INFO - Started process (PID=95764) to work on /opt/airflow/dags/bigC_1.py
[2025-01-19T14:59:47.304+0000] {processor.py:830} INFO - Processing file /opt/airflow/dags/bigC_1.py for tasks to queue
[2025-01-19T14:59:47.305+0000] {logging_mixin.py:188} INFO - [2025-01-19T14:59:47.305+0000] {dagbag.py:540} INFO - Filling up the DagBag from /opt/airflow/dags/bigC_1.py
[2025-01-19T14:59:47.416+0000] {logging_mixin.py:188} INFO - [2025-01-19T14:59:47.416+0000] {dagbag.py:350} ERROR - Failed to import: /opt/airflow/dags/bigC_1.py
Traceback (most recent call last):
  File "/home/airflow/.local/lib/python3.9/site-packages/airflow/models/dagbag.py", line 346, in parse
    loader.exec_module(new_module)
  File "<frozen importlib._bootstrap_external>", line 850, in exec_module
  File "<frozen importlib._bootstrap>", line 228, in _call_with_frames_removed
  File "/opt/airflow/dags/bigC_1.py", line 245, in <module>
    start >> [create_storage_task, create_table_task] >> empty1
  File "/home/airflow/.local/lib/python3.9/site-packages/airflow/models/taskmixin.py", line 104, in __rshift__
    self.set_downstream(other)
  File "/home/airflow/.local/lib/python3.9/site-packages/airflow/models/taskmixin.py", line 262, in set_downstream
    self._set_relatives(task_or_task_list, upstream=False, edge_modifier=edge_modifier)
  File "/home/airflow/.local/lib/python3.9/site-packages/airflow/models/taskmixin.py", line 232, in _set_relatives
    raise AirflowException(
airflow.exceptions.AirflowException: Tried to create relationships between tasks that don't have DAGs yet. Set the DAG for at least one task and try again: [<Task(EmptyOperator): start>, <Task(PythonOperator): create_storage>, <Task(PythonOperator): create_table>]
[2025-01-19T14:59:47.416+0000] {processor.py:842} WARNING - No viable dags retrieved from /opt/airflow/dags/bigC_1.py
[2025-01-19T14:59:47.427+0000] {processor.py:183} INFO - Processing /opt/airflow/dags/bigC_1.py took 0.127 seconds
[2025-01-19T15:00:17.610+0000] {processor.py:161} INFO - Started process (PID=95886) to work on /opt/airflow/dags/bigC_1.py
[2025-01-19T15:00:17.611+0000] {processor.py:830} INFO - Processing file /opt/airflow/dags/bigC_1.py for tasks to queue
[2025-01-19T15:00:17.612+0000] {logging_mixin.py:188} INFO - [2025-01-19T15:00:17.612+0000] {dagbag.py:540} INFO - Filling up the DagBag from /opt/airflow/dags/bigC_1.py
[2025-01-19T15:00:17.719+0000] {logging_mixin.py:188} INFO - [2025-01-19T15:00:17.719+0000] {dagbag.py:350} ERROR - Failed to import: /opt/airflow/dags/bigC_1.py
Traceback (most recent call last):
  File "/home/airflow/.local/lib/python3.9/site-packages/airflow/models/dagbag.py", line 346, in parse
    loader.exec_module(new_module)
  File "<frozen importlib._bootstrap_external>", line 850, in exec_module
  File "<frozen importlib._bootstrap>", line 228, in _call_with_frames_removed
  File "/opt/airflow/dags/bigC_1.py", line 245, in <module>
    start >> [create_storage_task, create_table_task] >> empty1
  File "/home/airflow/.local/lib/python3.9/site-packages/airflow/models/taskmixin.py", line 104, in __rshift__
    self.set_downstream(other)
  File "/home/airflow/.local/lib/python3.9/site-packages/airflow/models/taskmixin.py", line 262, in set_downstream
    self._set_relatives(task_or_task_list, upstream=False, edge_modifier=edge_modifier)
  File "/home/airflow/.local/lib/python3.9/site-packages/airflow/models/taskmixin.py", line 232, in _set_relatives
    raise AirflowException(
airflow.exceptions.AirflowException: Tried to create relationships between tasks that don't have DAGs yet. Set the DAG for at least one task and try again: [<Task(EmptyOperator): start>, <Task(PythonOperator): create_storage>, <Task(PythonOperator): create_table>]
[2025-01-19T15:00:17.719+0000] {processor.py:842} WARNING - No viable dags retrieved from /opt/airflow/dags/bigC_1.py
[2025-01-19T15:00:17.730+0000] {processor.py:183} INFO - Processing /opt/airflow/dags/bigC_1.py took 0.123 seconds
[2025-01-19T15:00:42.875+0000] {processor.py:161} INFO - Started process (PID=96003) to work on /opt/airflow/dags/bigC_1.py
[2025-01-19T15:00:42.875+0000] {processor.py:830} INFO - Processing file /opt/airflow/dags/bigC_1.py for tasks to queue
[2025-01-19T15:00:42.876+0000] {logging_mixin.py:188} INFO - [2025-01-19T15:00:42.876+0000] {dagbag.py:540} INFO - Filling up the DagBag from /opt/airflow/dags/bigC_1.py
[2025-01-19T15:00:42.985+0000] {logging_mixin.py:188} INFO - [2025-01-19T15:00:42.984+0000] {dagbag.py:350} ERROR - Failed to import: /opt/airflow/dags/bigC_1.py
Traceback (most recent call last):
  File "/home/airflow/.local/lib/python3.9/site-packages/airflow/models/dagbag.py", line 346, in parse
    loader.exec_module(new_module)
  File "<frozen importlib._bootstrap_external>", line 850, in exec_module
  File "<frozen importlib._bootstrap>", line 228, in _call_with_frames_removed
  File "/opt/airflow/dags/bigC_1.py", line 249, in <module>
    start >> [create_storage_task, create_table_task] >> empty1
  File "/home/airflow/.local/lib/python3.9/site-packages/airflow/models/taskmixin.py", line 104, in __rshift__
    self.set_downstream(other)
  File "/home/airflow/.local/lib/python3.9/site-packages/airflow/models/taskmixin.py", line 262, in set_downstream
    self._set_relatives(task_or_task_list, upstream=False, edge_modifier=edge_modifier)
  File "/home/airflow/.local/lib/python3.9/site-packages/airflow/models/taskmixin.py", line 232, in _set_relatives
    raise AirflowException(
airflow.exceptions.AirflowException: Tried to create relationships between tasks that don't have DAGs yet. Set the DAG for at least one task and try again: [<Task(EmptyOperator): start>, <Task(PythonOperator): create_storage>, <Task(PythonOperator): create_table>]
[2025-01-19T15:00:42.985+0000] {processor.py:842} WARNING - No viable dags retrieved from /opt/airflow/dags/bigC_1.py
[2025-01-19T15:00:42.996+0000] {processor.py:183} INFO - Processing /opt/airflow/dags/bigC_1.py took 0.125 seconds
[2025-01-19T15:01:13.080+0000] {processor.py:161} INFO - Started process (PID=96132) to work on /opt/airflow/dags/bigC_1.py
[2025-01-19T15:01:13.081+0000] {processor.py:830} INFO - Processing file /opt/airflow/dags/bigC_1.py for tasks to queue
[2025-01-19T15:01:13.082+0000] {logging_mixin.py:188} INFO - [2025-01-19T15:01:13.082+0000] {dagbag.py:540} INFO - Filling up the DagBag from /opt/airflow/dags/bigC_1.py
[2025-01-19T15:01:13.189+0000] {logging_mixin.py:188} INFO - [2025-01-19T15:01:13.189+0000] {dagbag.py:350} ERROR - Failed to import: /opt/airflow/dags/bigC_1.py
Traceback (most recent call last):
  File "/home/airflow/.local/lib/python3.9/site-packages/airflow/models/dagbag.py", line 346, in parse
    loader.exec_module(new_module)
  File "<frozen importlib._bootstrap_external>", line 850, in exec_module
  File "<frozen importlib._bootstrap>", line 228, in _call_with_frames_removed
  File "/opt/airflow/dags/bigC_1.py", line 249, in <module>
    start >> [create_storage_task, create_table_task] >> empty1
  File "/home/airflow/.local/lib/python3.9/site-packages/airflow/models/taskmixin.py", line 104, in __rshift__
    self.set_downstream(other)
  File "/home/airflow/.local/lib/python3.9/site-packages/airflow/models/taskmixin.py", line 262, in set_downstream
    self._set_relatives(task_or_task_list, upstream=False, edge_modifier=edge_modifier)
  File "/home/airflow/.local/lib/python3.9/site-packages/airflow/models/taskmixin.py", line 232, in _set_relatives
    raise AirflowException(
airflow.exceptions.AirflowException: Tried to create relationships between tasks that don't have DAGs yet. Set the DAG for at least one task and try again: [<Task(EmptyOperator): start>, <Task(PythonOperator): create_storage>, <Task(PythonOperator): create_table>]
[2025-01-19T15:01:13.189+0000] {processor.py:842} WARNING - No viable dags retrieved from /opt/airflow/dags/bigC_1.py
[2025-01-19T15:01:13.200+0000] {processor.py:183} INFO - Processing /opt/airflow/dags/bigC_1.py took 0.124 seconds
[2025-01-19T15:01:43.374+0000] {processor.py:161} INFO - Started process (PID=96261) to work on /opt/airflow/dags/bigC_1.py
[2025-01-19T15:01:43.376+0000] {processor.py:830} INFO - Processing file /opt/airflow/dags/bigC_1.py for tasks to queue
[2025-01-19T15:01:43.376+0000] {logging_mixin.py:188} INFO - [2025-01-19T15:01:43.376+0000] {dagbag.py:540} INFO - Filling up the DagBag from /opt/airflow/dags/bigC_1.py
[2025-01-19T15:01:43.487+0000] {logging_mixin.py:188} INFO - [2025-01-19T15:01:43.486+0000] {dagbag.py:350} ERROR - Failed to import: /opt/airflow/dags/bigC_1.py
Traceback (most recent call last):
  File "/home/airflow/.local/lib/python3.9/site-packages/airflow/models/dagbag.py", line 346, in parse
    loader.exec_module(new_module)
  File "<frozen importlib._bootstrap_external>", line 850, in exec_module
  File "<frozen importlib._bootstrap>", line 228, in _call_with_frames_removed
  File "/opt/airflow/dags/bigC_1.py", line 249, in <module>
    start >> [create_storage_task, create_table_task] >> empty1
  File "/home/airflow/.local/lib/python3.9/site-packages/airflow/models/taskmixin.py", line 104, in __rshift__
    self.set_downstream(other)
  File "/home/airflow/.local/lib/python3.9/site-packages/airflow/models/taskmixin.py", line 262, in set_downstream
    self._set_relatives(task_or_task_list, upstream=False, edge_modifier=edge_modifier)
  File "/home/airflow/.local/lib/python3.9/site-packages/airflow/models/taskmixin.py", line 232, in _set_relatives
    raise AirflowException(
airflow.exceptions.AirflowException: Tried to create relationships between tasks that don't have DAGs yet. Set the DAG for at least one task and try again: [<Task(EmptyOperator): start>, <Task(PythonOperator): create_storage>, <Task(PythonOperator): create_table>]
[2025-01-19T15:01:43.487+0000] {processor.py:842} WARNING - No viable dags retrieved from /opt/airflow/dags/bigC_1.py
[2025-01-19T15:01:43.496+0000] {processor.py:183} INFO - Processing /opt/airflow/dags/bigC_1.py took 0.125 seconds
[2025-01-19T15:02:13.579+0000] {processor.py:161} INFO - Started process (PID=96383) to work on /opt/airflow/dags/bigC_1.py
[2025-01-19T15:02:13.579+0000] {processor.py:830} INFO - Processing file /opt/airflow/dags/bigC_1.py for tasks to queue
[2025-01-19T15:02:13.580+0000] {logging_mixin.py:188} INFO - [2025-01-19T15:02:13.580+0000] {dagbag.py:540} INFO - Filling up the DagBag from /opt/airflow/dags/bigC_1.py
[2025-01-19T15:02:13.689+0000] {logging_mixin.py:188} INFO - [2025-01-19T15:02:13.688+0000] {dagbag.py:350} ERROR - Failed to import: /opt/airflow/dags/bigC_1.py
Traceback (most recent call last):
  File "/home/airflow/.local/lib/python3.9/site-packages/airflow/models/dagbag.py", line 346, in parse
    loader.exec_module(new_module)
  File "<frozen importlib._bootstrap_external>", line 850, in exec_module
  File "<frozen importlib._bootstrap>", line 228, in _call_with_frames_removed
  File "/opt/airflow/dags/bigC_1.py", line 249, in <module>
    start >> [create_storage_task, create_table_task] >> empty1
  File "/home/airflow/.local/lib/python3.9/site-packages/airflow/models/taskmixin.py", line 104, in __rshift__
    self.set_downstream(other)
  File "/home/airflow/.local/lib/python3.9/site-packages/airflow/models/taskmixin.py", line 262, in set_downstream
    self._set_relatives(task_or_task_list, upstream=False, edge_modifier=edge_modifier)
  File "/home/airflow/.local/lib/python3.9/site-packages/airflow/models/taskmixin.py", line 232, in _set_relatives
    raise AirflowException(
airflow.exceptions.AirflowException: Tried to create relationships between tasks that don't have DAGs yet. Set the DAG for at least one task and try again: [<Task(EmptyOperator): start>, <Task(PythonOperator): create_storage>, <Task(PythonOperator): create_table>]
[2025-01-19T15:02:13.689+0000] {processor.py:842} WARNING - No viable dags retrieved from /opt/airflow/dags/bigC_1.py
[2025-01-19T15:02:13.699+0000] {processor.py:183} INFO - Processing /opt/airflow/dags/bigC_1.py took 0.125 seconds
[2025-01-19T15:02:43.793+0000] {processor.py:161} INFO - Started process (PID=96512) to work on /opt/airflow/dags/bigC_1.py
[2025-01-19T15:02:43.794+0000] {processor.py:830} INFO - Processing file /opt/airflow/dags/bigC_1.py for tasks to queue
[2025-01-19T15:02:43.795+0000] {logging_mixin.py:188} INFO - [2025-01-19T15:02:43.795+0000] {dagbag.py:540} INFO - Filling up the DagBag from /opt/airflow/dags/bigC_1.py
[2025-01-19T15:02:43.901+0000] {logging_mixin.py:188} INFO - [2025-01-19T15:02:43.901+0000] {dagbag.py:350} ERROR - Failed to import: /opt/airflow/dags/bigC_1.py
Traceback (most recent call last):
  File "/home/airflow/.local/lib/python3.9/site-packages/airflow/models/dagbag.py", line 346, in parse
    loader.exec_module(new_module)
  File "<frozen importlib._bootstrap_external>", line 850, in exec_module
  File "<frozen importlib._bootstrap>", line 228, in _call_with_frames_removed
  File "/opt/airflow/dags/bigC_1.py", line 249, in <module>
    start >> [create_storage_task, create_table_task] >> empty1
  File "/home/airflow/.local/lib/python3.9/site-packages/airflow/models/taskmixin.py", line 104, in __rshift__
    self.set_downstream(other)
  File "/home/airflow/.local/lib/python3.9/site-packages/airflow/models/taskmixin.py", line 262, in set_downstream
    self._set_relatives(task_or_task_list, upstream=False, edge_modifier=edge_modifier)
  File "/home/airflow/.local/lib/python3.9/site-packages/airflow/models/taskmixin.py", line 232, in _set_relatives
    raise AirflowException(
airflow.exceptions.AirflowException: Tried to create relationships between tasks that don't have DAGs yet. Set the DAG for at least one task and try again: [<Task(EmptyOperator): start>, <Task(PythonOperator): create_storage>, <Task(PythonOperator): create_table>]
[2025-01-19T15:02:43.901+0000] {processor.py:842} WARNING - No viable dags retrieved from /opt/airflow/dags/bigC_1.py
[2025-01-19T15:02:43.911+0000] {processor.py:183} INFO - Processing /opt/airflow/dags/bigC_1.py took 0.122 seconds
[2025-01-19T15:03:14.021+0000] {processor.py:161} INFO - Started process (PID=96634) to work on /opt/airflow/dags/bigC_1.py
[2025-01-19T15:03:14.022+0000] {processor.py:830} INFO - Processing file /opt/airflow/dags/bigC_1.py for tasks to queue
[2025-01-19T15:03:14.023+0000] {logging_mixin.py:188} INFO - [2025-01-19T15:03:14.023+0000] {dagbag.py:540} INFO - Filling up the DagBag from /opt/airflow/dags/bigC_1.py
[2025-01-19T15:03:14.133+0000] {logging_mixin.py:188} INFO - [2025-01-19T15:03:14.132+0000] {dagbag.py:350} ERROR - Failed to import: /opt/airflow/dags/bigC_1.py
Traceback (most recent call last):
  File "/home/airflow/.local/lib/python3.9/site-packages/airflow/models/dagbag.py", line 346, in parse
    loader.exec_module(new_module)
  File "<frozen importlib._bootstrap_external>", line 850, in exec_module
  File "<frozen importlib._bootstrap>", line 228, in _call_with_frames_removed
  File "/opt/airflow/dags/bigC_1.py", line 249, in <module>
    start >> [create_storage_task, create_table_task] >> empty1
  File "/home/airflow/.local/lib/python3.9/site-packages/airflow/models/taskmixin.py", line 104, in __rshift__
    self.set_downstream(other)
  File "/home/airflow/.local/lib/python3.9/site-packages/airflow/models/taskmixin.py", line 262, in set_downstream
    self._set_relatives(task_or_task_list, upstream=False, edge_modifier=edge_modifier)
  File "/home/airflow/.local/lib/python3.9/site-packages/airflow/models/taskmixin.py", line 232, in _set_relatives
    raise AirflowException(
airflow.exceptions.AirflowException: Tried to create relationships between tasks that don't have DAGs yet. Set the DAG for at least one task and try again: [<Task(EmptyOperator): start>, <Task(PythonOperator): create_storage>, <Task(PythonOperator): create_table>]
[2025-01-19T15:03:14.133+0000] {processor.py:842} WARNING - No viable dags retrieved from /opt/airflow/dags/bigC_1.py
[2025-01-19T15:03:14.143+0000] {processor.py:183} INFO - Processing /opt/airflow/dags/bigC_1.py took 0.126 seconds
[2025-01-19T15:03:44.211+0000] {processor.py:161} INFO - Started process (PID=96763) to work on /opt/airflow/dags/bigC_1.py
[2025-01-19T15:03:44.212+0000] {processor.py:830} INFO - Processing file /opt/airflow/dags/bigC_1.py for tasks to queue
[2025-01-19T15:03:44.213+0000] {logging_mixin.py:188} INFO - [2025-01-19T15:03:44.213+0000] {dagbag.py:540} INFO - Filling up the DagBag from /opt/airflow/dags/bigC_1.py
[2025-01-19T15:03:44.320+0000] {logging_mixin.py:188} INFO - [2025-01-19T15:03:44.319+0000] {dagbag.py:350} ERROR - Failed to import: /opt/airflow/dags/bigC_1.py
Traceback (most recent call last):
  File "/home/airflow/.local/lib/python3.9/site-packages/airflow/models/dagbag.py", line 346, in parse
    loader.exec_module(new_module)
  File "<frozen importlib._bootstrap_external>", line 850, in exec_module
  File "<frozen importlib._bootstrap>", line 228, in _call_with_frames_removed
  File "/opt/airflow/dags/bigC_1.py", line 249, in <module>
    start >> [create_storage_task, create_table_task] >> empty1
  File "/home/airflow/.local/lib/python3.9/site-packages/airflow/models/taskmixin.py", line 104, in __rshift__
    self.set_downstream(other)
  File "/home/airflow/.local/lib/python3.9/site-packages/airflow/models/taskmixin.py", line 262, in set_downstream
    self._set_relatives(task_or_task_list, upstream=False, edge_modifier=edge_modifier)
  File "/home/airflow/.local/lib/python3.9/site-packages/airflow/models/taskmixin.py", line 232, in _set_relatives
    raise AirflowException(
airflow.exceptions.AirflowException: Tried to create relationships between tasks that don't have DAGs yet. Set the DAG for at least one task and try again: [<Task(EmptyOperator): start>, <Task(PythonOperator): create_storage>, <Task(PythonOperator): create_table>]
[2025-01-19T15:03:44.320+0000] {processor.py:842} WARNING - No viable dags retrieved from /opt/airflow/dags/bigC_1.py
[2025-01-19T15:03:44.332+0000] {processor.py:183} INFO - Processing /opt/airflow/dags/bigC_1.py took 0.125 seconds
[2025-01-19T15:04:14.419+0000] {processor.py:161} INFO - Started process (PID=96892) to work on /opt/airflow/dags/bigC_1.py
[2025-01-19T15:04:14.420+0000] {processor.py:830} INFO - Processing file /opt/airflow/dags/bigC_1.py for tasks to queue
[2025-01-19T15:04:14.421+0000] {logging_mixin.py:188} INFO - [2025-01-19T15:04:14.421+0000] {dagbag.py:540} INFO - Filling up the DagBag from /opt/airflow/dags/bigC_1.py
[2025-01-19T15:04:14.528+0000] {logging_mixin.py:188} INFO - [2025-01-19T15:04:14.528+0000] {dagbag.py:350} ERROR - Failed to import: /opt/airflow/dags/bigC_1.py
Traceback (most recent call last):
  File "/home/airflow/.local/lib/python3.9/site-packages/airflow/models/dagbag.py", line 346, in parse
    loader.exec_module(new_module)
  File "<frozen importlib._bootstrap_external>", line 850, in exec_module
  File "<frozen importlib._bootstrap>", line 228, in _call_with_frames_removed
  File "/opt/airflow/dags/bigC_1.py", line 249, in <module>
    start >> [create_storage_task, create_table_task] >> empty1
  File "/home/airflow/.local/lib/python3.9/site-packages/airflow/models/taskmixin.py", line 104, in __rshift__
    self.set_downstream(other)
  File "/home/airflow/.local/lib/python3.9/site-packages/airflow/models/taskmixin.py", line 262, in set_downstream
    self._set_relatives(task_or_task_list, upstream=False, edge_modifier=edge_modifier)
  File "/home/airflow/.local/lib/python3.9/site-packages/airflow/models/taskmixin.py", line 232, in _set_relatives
    raise AirflowException(
airflow.exceptions.AirflowException: Tried to create relationships between tasks that don't have DAGs yet. Set the DAG for at least one task and try again: [<Task(EmptyOperator): start>, <Task(PythonOperator): create_storage>, <Task(PythonOperator): create_table>]
[2025-01-19T15:04:14.528+0000] {processor.py:842} WARNING - No viable dags retrieved from /opt/airflow/dags/bigC_1.py
[2025-01-19T15:04:14.538+0000] {processor.py:183} INFO - Processing /opt/airflow/dags/bigC_1.py took 0.123 seconds
[2025-01-19T15:04:22.583+0000] {processor.py:161} INFO - Started process (PID=96902) to work on /opt/airflow/dags/bigC_1.py
[2025-01-19T15:04:22.584+0000] {processor.py:830} INFO - Processing file /opt/airflow/dags/bigC_1.py for tasks to queue
[2025-01-19T15:04:22.584+0000] {logging_mixin.py:188} INFO - [2025-01-19T15:04:22.584+0000] {dagbag.py:540} INFO - Filling up the DagBag from /opt/airflow/dags/bigC_1.py
[2025-01-19T15:04:22.691+0000] {logging_mixin.py:188} INFO - [2025-01-19T15:04:22.690+0000] {dagbag.py:350} ERROR - Failed to import: /opt/airflow/dags/bigC_1.py
Traceback (most recent call last):
  File "/home/airflow/.local/lib/python3.9/site-packages/airflow/models/dagbag.py", line 346, in parse
    loader.exec_module(new_module)
  File "<frozen importlib._bootstrap_external>", line 850, in exec_module
  File "<frozen importlib._bootstrap>", line 228, in _call_with_frames_removed
  File "/opt/airflow/dags/bigC_1.py", line 250, in <module>
    start >> [create_storage_task, create_table_task] >> empty1
  File "/home/airflow/.local/lib/python3.9/site-packages/airflow/models/taskmixin.py", line 104, in __rshift__
    self.set_downstream(other)
  File "/home/airflow/.local/lib/python3.9/site-packages/airflow/models/taskmixin.py", line 262, in set_downstream
    self._set_relatives(task_or_task_list, upstream=False, edge_modifier=edge_modifier)
  File "/home/airflow/.local/lib/python3.9/site-packages/airflow/models/taskmixin.py", line 232, in _set_relatives
    raise AirflowException(
airflow.exceptions.AirflowException: Tried to create relationships between tasks that don't have DAGs yet. Set the DAG for at least one task and try again: [<Task(EmptyOperator): start>, <Task(PythonOperator): create_storage>, <Task(PythonOperator): create_table>]
[2025-01-19T15:04:22.691+0000] {processor.py:842} WARNING - No viable dags retrieved from /opt/airflow/dags/bigC_1.py
[2025-01-19T15:04:22.701+0000] {processor.py:183} INFO - Processing /opt/airflow/dags/bigC_1.py took 0.122 seconds
[2025-01-19T15:04:52.788+0000] {processor.py:161} INFO - Started process (PID=97031) to work on /opt/airflow/dags/bigC_1.py
[2025-01-19T15:04:52.789+0000] {processor.py:830} INFO - Processing file /opt/airflow/dags/bigC_1.py for tasks to queue
[2025-01-19T15:04:52.790+0000] {logging_mixin.py:188} INFO - [2025-01-19T15:04:52.790+0000] {dagbag.py:540} INFO - Filling up the DagBag from /opt/airflow/dags/bigC_1.py
[2025-01-19T15:04:52.898+0000] {logging_mixin.py:188} INFO - [2025-01-19T15:04:52.897+0000] {dagbag.py:350} ERROR - Failed to import: /opt/airflow/dags/bigC_1.py
Traceback (most recent call last):
  File "/home/airflow/.local/lib/python3.9/site-packages/airflow/models/dagbag.py", line 346, in parse
    loader.exec_module(new_module)
  File "<frozen importlib._bootstrap_external>", line 850, in exec_module
  File "<frozen importlib._bootstrap>", line 228, in _call_with_frames_removed
  File "/opt/airflow/dags/bigC_1.py", line 250, in <module>
    start >> [create_storage_task, create_table_task] >> empty1
  File "/home/airflow/.local/lib/python3.9/site-packages/airflow/models/taskmixin.py", line 104, in __rshift__
    self.set_downstream(other)
  File "/home/airflow/.local/lib/python3.9/site-packages/airflow/models/taskmixin.py", line 262, in set_downstream
    self._set_relatives(task_or_task_list, upstream=False, edge_modifier=edge_modifier)
  File "/home/airflow/.local/lib/python3.9/site-packages/airflow/models/taskmixin.py", line 232, in _set_relatives
    raise AirflowException(
airflow.exceptions.AirflowException: Tried to create relationships between tasks that don't have DAGs yet. Set the DAG for at least one task and try again: [<Task(EmptyOperator): start>, <Task(PythonOperator): create_storage>, <Task(PythonOperator): create_table>]
[2025-01-19T15:04:52.898+0000] {processor.py:842} WARNING - No viable dags retrieved from /opt/airflow/dags/bigC_1.py
[2025-01-19T15:04:52.909+0000] {processor.py:183} INFO - Processing /opt/airflow/dags/bigC_1.py took 0.125 seconds
[2025-01-19T15:05:23.007+0000] {processor.py:161} INFO - Started process (PID=97160) to work on /opt/airflow/dags/bigC_1.py
[2025-01-19T15:05:23.008+0000] {processor.py:830} INFO - Processing file /opt/airflow/dags/bigC_1.py for tasks to queue
[2025-01-19T15:05:23.009+0000] {logging_mixin.py:188} INFO - [2025-01-19T15:05:23.009+0000] {dagbag.py:540} INFO - Filling up the DagBag from /opt/airflow/dags/bigC_1.py
[2025-01-19T15:05:23.114+0000] {logging_mixin.py:188} INFO - [2025-01-19T15:05:23.114+0000] {dagbag.py:350} ERROR - Failed to import: /opt/airflow/dags/bigC_1.py
Traceback (most recent call last):
  File "/home/airflow/.local/lib/python3.9/site-packages/airflow/models/dagbag.py", line 346, in parse
    loader.exec_module(new_module)
  File "<frozen importlib._bootstrap_external>", line 850, in exec_module
  File "<frozen importlib._bootstrap>", line 228, in _call_with_frames_removed
  File "/opt/airflow/dags/bigC_1.py", line 250, in <module>
    start >> [create_storage_task, create_table_task] >> empty1
  File "/home/airflow/.local/lib/python3.9/site-packages/airflow/models/taskmixin.py", line 104, in __rshift__
    self.set_downstream(other)
  File "/home/airflow/.local/lib/python3.9/site-packages/airflow/models/taskmixin.py", line 262, in set_downstream
    self._set_relatives(task_or_task_list, upstream=False, edge_modifier=edge_modifier)
  File "/home/airflow/.local/lib/python3.9/site-packages/airflow/models/taskmixin.py", line 232, in _set_relatives
    raise AirflowException(
airflow.exceptions.AirflowException: Tried to create relationships between tasks that don't have DAGs yet. Set the DAG for at least one task and try again: [<Task(EmptyOperator): start>, <Task(PythonOperator): create_storage>, <Task(PythonOperator): create_table>]
[2025-01-19T15:05:23.115+0000] {processor.py:842} WARNING - No viable dags retrieved from /opt/airflow/dags/bigC_1.py
[2025-01-19T15:05:23.125+0000] {processor.py:183} INFO - Processing /opt/airflow/dags/bigC_1.py took 0.121 seconds
[2025-01-19T15:05:53.469+0000] {processor.py:161} INFO - Started process (PID=97282) to work on /opt/airflow/dags/bigC_1.py
[2025-01-19T15:05:53.470+0000] {processor.py:830} INFO - Processing file /opt/airflow/dags/bigC_1.py for tasks to queue
[2025-01-19T15:05:53.471+0000] {logging_mixin.py:188} INFO - [2025-01-19T15:05:53.470+0000] {dagbag.py:540} INFO - Filling up the DagBag from /opt/airflow/dags/bigC_1.py
[2025-01-19T15:05:53.577+0000] {logging_mixin.py:188} INFO - [2025-01-19T15:05:53.577+0000] {dagbag.py:350} ERROR - Failed to import: /opt/airflow/dags/bigC_1.py
Traceback (most recent call last):
  File "/home/airflow/.local/lib/python3.9/site-packages/airflow/models/dagbag.py", line 346, in parse
    loader.exec_module(new_module)
  File "<frozen importlib._bootstrap_external>", line 850, in exec_module
  File "<frozen importlib._bootstrap>", line 228, in _call_with_frames_removed
  File "/opt/airflow/dags/bigC_1.py", line 250, in <module>
    start >> [create_storage_task, create_table_task] >> empty1
  File "/home/airflow/.local/lib/python3.9/site-packages/airflow/models/taskmixin.py", line 104, in __rshift__
    self.set_downstream(other)
  File "/home/airflow/.local/lib/python3.9/site-packages/airflow/models/taskmixin.py", line 262, in set_downstream
    self._set_relatives(task_or_task_list, upstream=False, edge_modifier=edge_modifier)
  File "/home/airflow/.local/lib/python3.9/site-packages/airflow/models/taskmixin.py", line 232, in _set_relatives
    raise AirflowException(
airflow.exceptions.AirflowException: Tried to create relationships between tasks that don't have DAGs yet. Set the DAG for at least one task and try again: [<Task(EmptyOperator): start>, <Task(PythonOperator): create_storage>, <Task(PythonOperator): create_table>]
[2025-01-19T15:05:53.577+0000] {processor.py:842} WARNING - No viable dags retrieved from /opt/airflow/dags/bigC_1.py
[2025-01-19T15:05:53.589+0000] {processor.py:183} INFO - Processing /opt/airflow/dags/bigC_1.py took 0.124 seconds
[2025-01-19T15:06:23.766+0000] {processor.py:161} INFO - Started process (PID=97411) to work on /opt/airflow/dags/bigC_1.py
[2025-01-19T15:06:23.766+0000] {processor.py:830} INFO - Processing file /opt/airflow/dags/bigC_1.py for tasks to queue
[2025-01-19T15:06:23.767+0000] {logging_mixin.py:188} INFO - [2025-01-19T15:06:23.767+0000] {dagbag.py:540} INFO - Filling up the DagBag from /opt/airflow/dags/bigC_1.py
[2025-01-19T15:06:23.874+0000] {logging_mixin.py:188} INFO - [2025-01-19T15:06:23.874+0000] {dagbag.py:350} ERROR - Failed to import: /opt/airflow/dags/bigC_1.py
Traceback (most recent call last):
  File "/home/airflow/.local/lib/python3.9/site-packages/airflow/models/dagbag.py", line 346, in parse
    loader.exec_module(new_module)
  File "<frozen importlib._bootstrap_external>", line 850, in exec_module
  File "<frozen importlib._bootstrap>", line 228, in _call_with_frames_removed
  File "/opt/airflow/dags/bigC_1.py", line 250, in <module>
    start >> [create_storage_task, create_table_task] >> empty1
  File "/home/airflow/.local/lib/python3.9/site-packages/airflow/models/taskmixin.py", line 104, in __rshift__
    self.set_downstream(other)
  File "/home/airflow/.local/lib/python3.9/site-packages/airflow/models/taskmixin.py", line 262, in set_downstream
    self._set_relatives(task_or_task_list, upstream=False, edge_modifier=edge_modifier)
  File "/home/airflow/.local/lib/python3.9/site-packages/airflow/models/taskmixin.py", line 232, in _set_relatives
    raise AirflowException(
airflow.exceptions.AirflowException: Tried to create relationships between tasks that don't have DAGs yet. Set the DAG for at least one task and try again: [<Task(EmptyOperator): start>, <Task(PythonOperator): create_storage>, <Task(PythonOperator): create_table>]
[2025-01-19T15:06:23.874+0000] {processor.py:842} WARNING - No viable dags retrieved from /opt/airflow/dags/bigC_1.py
[2025-01-19T15:06:23.884+0000] {processor.py:183} INFO - Processing /opt/airflow/dags/bigC_1.py took 0.122 seconds
[2025-01-19T15:06:54.217+0000] {processor.py:161} INFO - Started process (PID=97540) to work on /opt/airflow/dags/bigC_1.py
[2025-01-19T15:06:54.217+0000] {processor.py:830} INFO - Processing file /opt/airflow/dags/bigC_1.py for tasks to queue
[2025-01-19T15:06:54.218+0000] {logging_mixin.py:188} INFO - [2025-01-19T15:06:54.218+0000] {dagbag.py:540} INFO - Filling up the DagBag from /opt/airflow/dags/bigC_1.py
[2025-01-19T15:06:54.329+0000] {logging_mixin.py:188} INFO - [2025-01-19T15:06:54.329+0000] {dagbag.py:350} ERROR - Failed to import: /opt/airflow/dags/bigC_1.py
Traceback (most recent call last):
  File "/home/airflow/.local/lib/python3.9/site-packages/airflow/models/dagbag.py", line 346, in parse
    loader.exec_module(new_module)
  File "<frozen importlib._bootstrap_external>", line 850, in exec_module
  File "<frozen importlib._bootstrap>", line 228, in _call_with_frames_removed
  File "/opt/airflow/dags/bigC_1.py", line 250, in <module>
    start >> [create_storage_task, create_table_task] >> empty1
  File "/home/airflow/.local/lib/python3.9/site-packages/airflow/models/taskmixin.py", line 104, in __rshift__
    self.set_downstream(other)
  File "/home/airflow/.local/lib/python3.9/site-packages/airflow/models/taskmixin.py", line 262, in set_downstream
    self._set_relatives(task_or_task_list, upstream=False, edge_modifier=edge_modifier)
  File "/home/airflow/.local/lib/python3.9/site-packages/airflow/models/taskmixin.py", line 232, in _set_relatives
    raise AirflowException(
airflow.exceptions.AirflowException: Tried to create relationships between tasks that don't have DAGs yet. Set the DAG for at least one task and try again: [<Task(EmptyOperator): start>, <Task(PythonOperator): create_storage>, <Task(PythonOperator): create_table>]
[2025-01-19T15:06:54.329+0000] {processor.py:842} WARNING - No viable dags retrieved from /opt/airflow/dags/bigC_1.py
[2025-01-19T15:06:54.339+0000] {processor.py:183} INFO - Processing /opt/airflow/dags/bigC_1.py took 0.126 seconds
[2025-01-19T15:07:24.679+0000] {processor.py:161} INFO - Started process (PID=97662) to work on /opt/airflow/dags/bigC_1.py
[2025-01-19T15:07:24.680+0000] {processor.py:830} INFO - Processing file /opt/airflow/dags/bigC_1.py for tasks to queue
[2025-01-19T15:07:24.681+0000] {logging_mixin.py:188} INFO - [2025-01-19T15:07:24.681+0000] {dagbag.py:540} INFO - Filling up the DagBag from /opt/airflow/dags/bigC_1.py
[2025-01-19T15:07:24.873+0000] {logging_mixin.py:188} INFO - [2025-01-19T15:07:24.873+0000] {dagbag.py:350} ERROR - Failed to import: /opt/airflow/dags/bigC_1.py
Traceback (most recent call last):
  File "/home/airflow/.local/lib/python3.9/site-packages/airflow/models/dagbag.py", line 346, in parse
    loader.exec_module(new_module)
  File "<frozen importlib._bootstrap_external>", line 850, in exec_module
  File "<frozen importlib._bootstrap>", line 228, in _call_with_frames_removed
  File "/opt/airflow/dags/bigC_1.py", line 250, in <module>
    start >> [create_storage_task, create_table_task] >> empty1
  File "/home/airflow/.local/lib/python3.9/site-packages/airflow/models/taskmixin.py", line 104, in __rshift__
    self.set_downstream(other)
  File "/home/airflow/.local/lib/python3.9/site-packages/airflow/models/taskmixin.py", line 262, in set_downstream
    self._set_relatives(task_or_task_list, upstream=False, edge_modifier=edge_modifier)
  File "/home/airflow/.local/lib/python3.9/site-packages/airflow/models/taskmixin.py", line 232, in _set_relatives
    raise AirflowException(
airflow.exceptions.AirflowException: Tried to create relationships between tasks that don't have DAGs yet. Set the DAG for at least one task and try again: [<Task(EmptyOperator): start>, <Task(PythonOperator): create_storage>, <Task(PythonOperator): create_table>]
[2025-01-19T15:07:24.874+0000] {processor.py:842} WARNING - No viable dags retrieved from /opt/airflow/dags/bigC_1.py
[2025-01-19T15:07:24.883+0000] {processor.py:183} INFO - Processing /opt/airflow/dags/bigC_1.py took 0.208 seconds
[2025-01-19T15:07:30.958+0000] {processor.py:161} INFO - Started process (PID=97699) to work on /opt/airflow/dags/bigC_1.py
[2025-01-19T15:07:30.959+0000] {processor.py:830} INFO - Processing file /opt/airflow/dags/bigC_1.py for tasks to queue
[2025-01-19T15:07:30.960+0000] {logging_mixin.py:188} INFO - [2025-01-19T15:07:30.960+0000] {dagbag.py:540} INFO - Filling up the DagBag from /opt/airflow/dags/bigC_1.py
[2025-01-19T15:07:31.151+0000] {processor.py:840} INFO - DAG(s) 'BigC' retrieved from /opt/airflow/dags/bigC_1.py
[2025-01-19T15:07:31.203+0000] {logging_mixin.py:188} INFO - [2025-01-19T15:07:31.203+0000] {override.py:1829} INFO - Created Permission View: can read on DAG:BigC
[2025-01-19T15:07:31.208+0000] {logging_mixin.py:188} INFO - [2025-01-19T15:07:31.207+0000] {override.py:1829} INFO - Created Permission View: can delete on DAG:BigC
[2025-01-19T15:07:31.211+0000] {logging_mixin.py:188} INFO - [2025-01-19T15:07:31.211+0000] {override.py:1829} INFO - Created Permission View: can edit on DAG:BigC
[2025-01-19T15:07:31.211+0000] {logging_mixin.py:188} INFO - [2025-01-19T15:07:31.211+0000] {dag.py:3096} INFO - Sync 1 DAGs
[2025-01-19T15:07:31.216+0000] {logging_mixin.py:188} INFO - [2025-01-19T15:07:31.216+0000] {dag.py:3118} INFO - Creating ORM DAG for BigC
[2025-01-19T15:07:31.217+0000] {logging_mixin.py:188} INFO - [2025-01-19T15:07:31.217+0000] {dag.py:3954} INFO - Setting next_dagrun for BigC to None, run_after=None
[2025-01-19T15:07:31.223+0000] {processor.py:183} INFO - Processing /opt/airflow/dags/bigC_1.py took 0.268 seconds
[2025-01-19T15:08:01.566+0000] {processor.py:161} INFO - Started process (PID=97885) to work on /opt/airflow/dags/bigC_1.py
[2025-01-19T15:08:01.566+0000] {processor.py:830} INFO - Processing file /opt/airflow/dags/bigC_1.py for tasks to queue
[2025-01-19T15:08:01.567+0000] {logging_mixin.py:188} INFO - [2025-01-19T15:08:01.567+0000] {dagbag.py:540} INFO - Filling up the DagBag from /opt/airflow/dags/bigC_1.py
[2025-01-19T15:08:01.781+0000] {processor.py:840} INFO - DAG(s) 'BigC' retrieved from /opt/airflow/dags/bigC_1.py
[2025-01-19T15:08:01.796+0000] {logging_mixin.py:188} INFO - [2025-01-19T15:08:01.796+0000] {dag.py:3096} INFO - Sync 1 DAGs
[2025-01-19T15:08:01.803+0000] {logging_mixin.py:188} INFO - [2025-01-19T15:08:01.802+0000] {dag.py:3954} INFO - Setting next_dagrun for BigC to None, run_after=None
[2025-01-19T15:08:01.813+0000] {processor.py:183} INFO - Processing /opt/airflow/dags/bigC_1.py took 0.252 seconds
